Workbook

Sheet ①案件マスタ
A1: 民間廃棄物収集受託案件 案件マスタ
A2: 案件情報 | H2: 拠点規模 | K2: 売上参照（自動）
A3: 案件ID | B3: 案件名 | C3: カテゴリ | D3: 担当プレフィックス | E3: ドライバー数 | F3: ステータス | G3: 備考 | H3: 拠点数 | I3: 週間回収量(kg) | J3: 月間回収量(kg) | K3: 直近月売上 (合計) | L3: 直近月 原価(入力) | M3: 直近月 粗利率
A4: C001 | B4: 東急グループ案件 | C4: 東急グループ | D4: TK- | E4: 7 | F4: 稼働中 | H4: 93 | I4: 6312 | J4: =I4*4.33 | K4: =IFERROR(SUMPRODUCT(IFERROR(VLOOKUP(MAX(⑤売上原票!$A$5:$A$100),⑤売上原票!$A:$P,{3,4,5,6,7,8,9,10,11,12,13},0),0)*IFERROR(INDEX(⑥科目マッピング!$D$5:$F$15,,1),0)/100),"算出中") | L4: 0 | M4: =IF(AND(K4<>"算出中",L4<>0),(K4-L4)/K4,"")
A5: C002 | B5: 都営地下鉄案件 | C5: 都営地下鉄 | D5: MT- | E5: 6 | F5: 稼働中 | H5: 110 | I5: 8930 | J5: =I5*4.33 | K5: =IFERROR(SUMPRODUCT(IFERROR(VLOOKUP(MAX(⑤売上原票!$A$5:$A$100),⑤売上原票!$A:$P,{3,4,5,6,7,8,9,10,11,12,13},0),0)*IFERROR(INDEX(⑥科目マッピング!$D$5:$F$15,,2),0)/100),"算出中") | L5: 0 | M5: =IF(AND(K5<>"算出中",L5<>0),(K5-L5)/K5,"")
A6: C003 | B6: 一般事業者案件 | C6: 一般事業者 | D6: GN- | E6: 13 | F6: 稼働中 | H6: 302 | I6: 37561 | J6: =I6*4.33 | K6: =IFERROR(SUMPRODUCT(IFERROR(VLOOKUP(MAX(⑤売上原票!$A$5:$A$100),⑤売上原票!$A:$P,{3,4,5,6,7,8,9,10,11,12,13},0),0)*IFERROR(INDEX(⑥科目マッピング!$D$5:$F$15,,3),0)/100),"算出中") | L6: 0 | M6: =IF(AND(K6<>"算出中",L6<>0),(K6-L6)/K6,"")

Sheet ②拠点マスター
A1: 拠点マスター（505拠点）
A2: 拠点基本情報
A3: 拠点コード | B3: 拠点名 | C3: カテゴリ | D3: 住所 | E3: 回収曜日 | F3: 担当ドライバー | G3: 廃棄物種別 | H3: 週間回収量(kg)
A4: TK-001 | B4: TOKS 不動前駅 | C4: 東急グループ | D4: 東京都品川区西五反田５－１２－１ | E4: 金 | F4: 中條 | G4: 不燃物 | H4: 5
A5: TK-002 | B5: TOKS 中目黒駅 | C5: 東急グループ | D5: 東京都目黒区上目黒３－４－１ | E5: 土・月・木・水・火・金 | F5: 千葉・長谷川 | G5: 一般廃・産廃 | H5: 98
A6: TK-003 | B6: TOKS 二子玉川駅 | C6: 東急グループ | D6: 東京都世田谷区玉川２－２２－１３ | E6: ・日・木・火 | F6: 中條・千葉・長野 | G6: 一般廃・産廃 | H6: 16
A7: TK-004 | B7: TOKS 五反田駅店 | C7: 東急グループ | D7: 東京都品川区東五反田２－１－１ | E7: 木・火・金 | F7: 中條 | G7: 不燃物・瓶缶・資源 | H7: 10
A8: TK-005 | B8: TOKS 代官山駅 | C8: 東急グループ | D8: 東京都渋谷区代官山町１９－１ | E8: 土 | F8: 長野 | G8: 産廃 | H8: 10
A9: TK-006 | B9: TOKS 学芸大学駅 | C9: 東急グループ | D9: 東京都目黒区鷹番３－２－１ | E9: ・土・月・木・水・火・金 | F9: 千葉・長谷川 | G9: 一般廃・産廃 | H9: 56
A10: TK-007 | B10: TOKS 用賀駅 | C10: 東急グループ | D10: 東京都世田谷区用賀２－３９ | E10: 木 | F10: 長野 | G10: 産廃 | H10: 20
A11: TK-008 | B11: TOKS 田園都市渋谷駅 | C11: 東急グループ | D11: 東京都渋谷区道玄坂２－１－１ | E11: 土・月・水・金 | F11: 和田・荻野・長野 | G11: 段ボール・産廃 | H11: 14
A12: TK-009 | B12: TOKS 目黒駅 | C12: 東急グループ | D12: 東京都品川区上大崎４－２－１ | E12: 水・金 | F12: 中條・千葉 | G12: 瓶缶・産廃 | H12: 3
A13: TK-010 | B13: TOKS 蒲田改札口店 | C13: 東急グループ | D13: 東京都大田区西蒲田７－６９－１ | E13: 水 | F13: 千葉 | G13: 産廃 | H13: 20
A14: TK-011 | B14: ローソン＋TOKS 三軒茶屋店 | C14: 東急グループ | D14: 東京都世田谷区太子堂２－１５ | F14: 千葉 | G14: 産廃 | H14: 40
A15: TK-012 | B15: ローソン＋TOKS 多摩川駅店 | C15: 東急グループ | D15: 東京都大田区田園調布１－５３－８ | E15: 土・木 | F15: 和田・荻野・長野 | G15: 段ボール・産廃 | H15: 120
A16: TK-013 | B16: ローソン＋TOKS 大井町駅 | C16: 東急グループ | D16: 東京都品川区大井１－１－１ | E16: 月・木・水・金 | F16: 中條・千葉 | G16: 段ボール・産廃 | H16: 109
A17: TK-014 | B17: ローソン＋TOKS 田園調布駅 | C17: 東急グループ | D17: 東京都大田区田園調布３－２５－１８ | E17: ・木・火 | F17: 千葉・長野 | G17: 産廃 | H17: 0
A18: TK-015 | B18: ローソン＋TOKS 石川台店 | C18: 東急グループ | D18: 東京都大田区東雪谷２－２３－１ | E18: ・土・月・木・水・火・金 | F18: 中條・千葉・藤内 | G18: 段ボール・産廃・資源 | H18: 180
A19: TK-016 | B19: ローソン＋TOKS 自由が丘駅 | C19: 東急グループ | D19: 東京都目黒区自由が丘１－３０－１ | E19: ・日・木・火 | F19: 中條・千葉 | G19: 一般廃・産廃 | H19: 53
A20: TK-017 | B20: ローソン＋toks 三軒茶屋店 | C20: 東急グループ | D20: 東京都世田谷区太子堂２－１５ | E20: 土・月・木・火 | F20: 中條・和田・荻野・長野 | G20: 段ボール・産廃・資源 | H20: 85
A21: TK-018 | B21: 東急ウェルネス本社事務所 | C21: 東急グループ | D21: 東京都品川区平塚２－１８－１９ | E21: 金 | F21: 中條 | G21: 瓶缶 | H21: 6
A22: TK-019 | B22: 東急グルメフロント | C22: 東急グループ | D22: 東京都目黒区碑文谷６－７－２２ | E22: 土・月・木・水・火・金 | F22: 千葉・長谷川 | G22: 一般廃・産廃 | H22: 230
A23: TK-020 | B23: 東急ストア 二子玉川駅構内店 | C23: 東急グループ | D23: 東京都世田谷区玉川２－２２－１３ | E23: ・日・木・火 | F23: 中條・千葉・長野 | G23: 一般廃・産廃 | H23: 22
A24: TK-021 | B24: 東急ストア 自由が丘駅構内 | C24: 東急グループ | D24: 東京都目黒区自由が丘１－３０－１ | E24: ・木・火 | F24: 千葉 | G24: 産廃 | H24: 18
A25: TK-022 | B25: 東急プロパティマネジメントサポートセンター | C25: 東急グループ | D25: 東京都世田谷区玉川１－１１－５ | E25: ・土・木・火 | F25: 千葉・和田・荻野・長野 | G25: 段ボール・産廃 | H25: 60
A26: TK-023 | B26: 東急プロパティマネジメント多摩川班 | C26: 東急グループ | D26: 東京都大田区田園調布１－５３－８ | E26: ・土・木・火 | F26: 中條・千葉・和田・荻野・長野 | G26: 段ボール・産廃・資源 | H26: 90
... A31: TK-028 | B31: 東急雪が谷大塚駅 | C31: 東急グループ | D31: 東京都大田区南雪谷２－２－１６ | E31: ・月・木・火 | F31: 中條・千葉 | G31: 段ボール・産廃 | H31: 115
A32: TK-029 | B32: 東急電鉄 三軒茶屋（世田谷線） | C32: 東急グループ | D32: 東京都世田谷区太子堂４－１ | F32: 千葉 | G32: 産廃 | H32: 6
A33: TK-030 | B33: 東急電鉄 三軒茶屋（田園都市線） | C33: 東急グループ | D33: 東京都世田谷区太子堂２－１５ | F33: 千葉 | G33: 産廃 | H33: 60
A34: TK-031 | B34: 東急電鉄 上町駅 | C34: 東急グループ | D34: 東京都世田谷区世田谷３－４－３ | F34: 千葉 | G34: 産廃 | H34: 0
A35: TK-032 | B35: 東急電鉄 下丸子駅 | C35: 東急グループ | D35: 東京都大田区下丸子３－７－１ | E35: 火 | F35: 千葉 | G35: 産廃 | H35: 40
A36: TK-033 | B36: 東急電鉄 下神明駅 | C36: 東急グループ | D36: 東京都品川区西品川１－２９－６ | E36: 金 | F36: 中條 | G36: 不燃物 | H36: 5
A37: TK-034 | B37: 東急電鉄 下高井戸駅 | C37: 東急グループ | D37: 東京都世田谷区松原３－２９－１７ | E37: 土・木・火 | F37: 和田・荻野・藤内・長谷川・長野 | G37: 一般廃・段ボール・産廃 | H37: 87
A38: TK-035 | B38: 東急電鉄 不動前駅 | C38: 東急グループ | D38: 東京都品川区西五反田５－１２－１ | E38: 金 | F38: 中條 | G38: 不燃物 | H38: 0
A39: TK-036 | B39: 東急電鉄 中延駅 | C39: 東急グループ | D39: 東京都品川区中延４－５－５ | E39: 金 | F39: 中條 | G39: 不燃物 | H39: 0
A40: TK-037 | B40: 東急電鉄 中目黒駅 | C40: 東急グループ | D40: 東京都目黒区上目黒３－４－１ | E40: 土・月・木・水・火・金 | F40: 中條・千葉・藤内・長谷川 | G40: 一般廃・不燃物・段ボール・産廃 | H40: 425
A41: TK-038 | B41: 東急電鉄 久が原駅 | C41: 東急グループ | D41: 東京都大田区南久が原２－６－１０ | E41: 木 | F41: 千葉 | G41: 産廃 | H41: 20
A42: TK-039 | B42: 東急電鉄 二子玉川乗務区 | C42: 東急グループ | D42: 東京都世田谷区玉川１－１１－５ | E42: 土 | F42: 和田・荻野 | G42: 段ボール | H42: 0
A43: TK-040 | B43: 東急電鉄 二子玉川信通事務所 | C43: 東急グループ | D43: 東京都世田谷区玉川１－１１－５ | E43: ・木・火 | F43: 千葉・長野 | G43: 産廃 | H43: 34
A44: TK-041 | B44: 東急電鉄 二子玉川駅 | C44: 東急グループ | D44: 東京都世田谷区玉川２－２２－１３ | E44: ・土・月・木・水・火・金 | F44: 千葉・和田・荻野・藤内・長野 | G44: 段ボール・産廃 | H44: 400
...

Sheet ③月次採算入力
A1: 月次採算入力シート（案件別） ★黄緑セル=売上原票から自動参照
A2: 【売上の自動連携】 E列〜H列の売上は ⑤売上原票 と ⑥科目-案件マッピング を参照して自動計算します。 集計月(D列)に YYYY-MM 形式で入力してください。
A3: 案件情報 | E3: 売上（⑤⑥から自動参照） | J3: 原 価（入力欄） | R3: 採 算
A4: 案件ID | B4: 案件名 | C4: カテゴリ | D4: 集計月 (YYYY-MM) | E4: ●運送 (612-1) | F4: ●入札 (612-2) | G4: ●板橋 (615-1) | H4: ●その他 | I4: 売上合計 | J4: 人件費 | K4: 燃料費 | L4: 車両維持費 | M4: 中間処理費 | N4: 搬入運搬費 | O4: 電子M代行費 | P4: 管理費 | Q4: 原価合計 | R4: 粗利益 | S4: 粗利率 | T4: 採算判定 | U4: 前月比 売上 | V4: 備考
A5: C001 | B5: 東急グループ案件 | C5: 東急グループ | D5: 2025-05 | E5: =IFERROR(VLOOKUP(D5,⑤売上原票!$A:$P,3,0)*VLOOKUP("612-1",⑥科目マッピング!$A:$F,4,0)/100,0) | F5: =IFERROR(VLOOKUP(D5,⑤売上原票!$A:$P,4,0)*VLOOKUP("612-2",⑥科目マッピング!$A:$F,4,0)/100,0) | G5: =IFERROR(VLOOKUP(D5,⑤売上原票!$A:$P,10,0)*VLOOKUP("615-1",⑥科目マッピング!$A:$F,4,0)/100,0) | H5: =IFERROR(VLOOKUP(D5,⑤売上原票!$A:$P,5,0)*VLOOKUP("613-1",⑥科目マッピング!$A:$F,4,0)/100,0)+IFERROR(VLOOKUP(D5,⑤売上原票!$A:$P,6,0)*VLOOKUP("613-2",⑥科目マッピング!$A:$F,4,0)/100,0)+IFERROR(VLOOKUP(D5,⑤売上原票!$A:$P,7,0)*VLOOKUP("614-1",⑥科目マッピング!$A:$F,4,0)/100,0)+IFERROR(VLOOKUP(D5,⑤売上原票!$A:$P,8,0)*VLOOKUP("614-2",⑥科目マッピング!$A:$F,4,0)/100,0)+IFERROR(VLOOKUP(D5,⑤売上原票!$A:$P,9,0)*VLOOKUP("614-3",⑥科目マッピング!$A:$F,4,0)/100,0)+IFERROR(VLOOKUP(D5,⑤売上原票!$A:$P,11,0)*VLOOKUP("615-2",⑥科目マッピング!$A:$F,4,0)/100,0)+IFERROR(VLOOKUP(D5,⑤売上原票!$A:$P,12,0)*VLOOKUP("615-3",⑥科目マッピング!$A:$F,4,0)/100,0)+IFERROR(VLOOKUP(D5,⑤売上原票!$A:$P,13,0)*VLOOKUP("615-4",⑥科目マッピング!$A:$F,4,0)/100,0) | I5: =E5+F5+G5+H5 | J5: 680000 | K5: 185000 | L5: 95000 | M5: 620000 | N5: 85000 | O5: 45000 | P5: 120000 | Q5: =J5+K5+L5+M5+N5+O5+P5 | R5: =I5-Q5 | S5: =IF(I5<>0,R5/I5,0) | T5: =IF(S5>=0.25,"◎ 優良",IF(S5>=0.15,"○ 良好",IF(S5>=0.05,"△ 要注意","× 赤字"))) | U5: —
A6: C001 | B6: 東急グループ案件 | C6: 東急グループ | D6: 2025-06 | E6: =IFERROR(VLOOKUP(D6,⑤売上原票!$A:$P,3,0)*VLOOKUP("612-1",⑥科目マッピング!$A:$F,4,0)/100,0) | F6: =IFERROR(VLOOKUP(D6,⑤売上原票!$A:$P,4,0)*VLOOKUP("612-2",⑥科目マッピング!$A:$F,4,0)/100,0) | G6: =IFERROR(VLOOKUP(D6,⑤売上原票!$A:$P,10,0)*VLOOKUP("615-1",⑥科目マッピング!$A:$F,4,0)/100,0) | H6: =IFERROR(VLOOKUP(D6,⑤売上原票!$A:$P,5,0)*VLOOKUP("613-1",⑥科目マッピング!$A:$F,4,0)/100,0)+IFERROR(VLOOKUP(D6,⑤売上原票!$A:$P,6,0)*VLOOKUP("613-2",⑥科目マッピング!$A:$F,4,0)/100,0)+IFERROR(VLOOKUP(D6,⑤売上原票!$A:$P,7,0)*VLOOKUP("614-1",⑥科目マッピング!$A:$F,4,0)/100,0)+IFERROR(VLOOKUP(D6,⑤売上原票!$A:$P,8,0)*VLOOKUP("614-2",⑥科目マッピング!$A:$F,4,0)/100,0)+IFERROR(VLOOKUP(D6,⑤売上原票!$A:$P,9,0)*VLOOKUP("614-3",⑥科目マッピング!$A:$F,4,0)/100,0)+IFERROR(VLOOKUP(D6,⑤売上原票!$A:$P,11,0)*VLOOKUP("615-2",⑥科目マッピング!$A:$F,4,0)/100,0)+IFERROR(VLOOKUP(D6,⑤売上原票!$A:$P,12,0)*VLOOKUP("615-3",⑥科目マッピング!$A:$F,4,0)/100,0)+IFERROR(VLOOKUP(D6,⑤売上原票!$A:$P,13,0)*VLOOKUP("615-4",⑥科目マッピング!$A:$F,4,0)/100,0) | I6: =E6+F6+G6+H6 | J6: 690000 | K6: 195000 | L6: 98000 | M6: 635000 | N6: 90000 | O6: 47000 | P6: 125000 | Q6: =J6+K6+L6+M6+N6+O6+P6 | R6: =I6-Q6 | S6: =IF(I6<>0,R6/I6,0) | T6: =IF(S6>=0.25,"◎ 優良",IF(S6>=0.15,"○ 良好",IF(S6>=0.05,"△ 要注意","× 赤字"))) | U6: =IF(I5<>0,I6/I5-1,"")
A7: C001 | B7: 東急グループ案件 | C7: 東急グループ | D7: 2025-07 | E7: =IFERROR(VLOOKUP(D7,⑤売上原票!$A:$P,3,0)*VLOOKUP("612-1",⑥科目マッピング!$A:$F,4,0)/100,0) | F7: =IFERROR(VLOOKUP(D7,⑤売上原票!$A:$P,4,0)*VLOOKUP("612-2",⑥科目マッピング!$A:$F,4,0)/100,0) | G7: =IFERROR(VLOOKUP(D7,⑤売上原票!$A:$P,10,0)*VLOOKUP("615-1",⑥科目マッピング!$A:$F,4,0)/100,0) | H7: =IFERROR(VLOOKUP(D7,⑤売上原票!$A:$P,5,0)*VLOOKUP("613-1",⑥科目マッピング!$A:$F,4,0)/100,0)+IFERROR(VLOOKUP(D7,⑤売上原票!$A:$P,6,0)*VLOOKUP("613-2",⑥科目マッピング!$A:$F,4,0)/100,0)+IFERROR(VLOOKUP(D7,⑤売上原票!$A:$P,7,0)*VLOOKUP("614-1",⑥科目マッピング!$A:$F,4,0)/100,0)+IFERROR(VLOOKUP(D7,⑤売上原票!$A:$P,8,0)*VLOOKUP("614-2",⑥科目マッピング!$A:$F,4,0)/100,0)+IFERROR(VLOOKUP(D7,⑤売上原票!$A:$P,9,0)*VLOOKUP("614-3",⑥科目マッピング!$A:$F,4,0)/100,0)+IFERROR(VLOOKUP(D7,⑤売上原票!$A:$P,11,0)*VLOOKUP("615-2",⑥科目マッピング!$A:$F,4,0)/100,0)+IFERROR(VLOOKUP(D7,⑤売上原票!$A:$P,12,0)*VLOOKUP("615-3",⑥科目マッピング!$A:$F,4,0)/100,0)+IFERROR(VLOOKUP(D7,⑤売上原票!$A:$P,13,0)*VLOOKUP("615-4",⑥科目マッピング!$A:$F,4,0)/100,0) | I7: =E7+F7+G7+H7 | J7: 705000 | K7: 198000 | L7: 100000 | M7: 648000 | N7: 92000 | O7: 48000 | P7: 128000 | Q7: =J7+K7+L7+M7+N7+O7+P7 | R7: =I7-Q7 | S7: =IF(I7<>0,R7/I7,0) | T7: =IF(S7>=0.25,"◎ 優良",IF(S7>=0.15,"○ 良好",IF(S7>=0.05,"△ 要注意","× 赤字"))) | U7: =IF(I6<>0,I7/I6-1,"")
A8: C001 | B8: 東急グループ案件 | C8: 東急グループ | D8: 2025-08 | E8: =IFERROR(VLOOKUP(D8,⑤売上原票!$A:$P,3,0)*VLOOKUP("612-1",⑥科目マッピング!$A:$F,4,0)/100,0) | F8: =IFERROR(VLOOKUP(D8,⑤売上原票!$A:$P,4,0)*VLOOKUP("612-2",⑥科目マッピング!$A:$F,4,0)/100,0) | G8: =IFERROR(VLOOKUP(D8,⑤売上原票!$A:$P,10,0)*VLOOKUP("615-1",⑥科目マッピング!$A:$F,4,0)/100,0) | H8: =IFERROR(VLOOKUP(D8,⑤売上原票!$A:$P,5,0)*VLOOKUP("613-1",⑥科目マッピング!$A:$F,4,0)/100,0)+IFERROR(VLOOKUP(D8,⑤売上原票!$A:$P,6,0)*VLOOKUP("613-2",⑥科目マッピング!$A:$F,4,0)/100,0)+IFERROR(VLOOKUP(D8,⑤売上原票!$A:$P,7,0)*VLOOKUP("614-1",⑥科目マッピング!$A:$F,4,0)/100,0)+IFERROR(VLOOKUP(D8,⑤売上原票!$A:$P,8,0)*VLOOKUP("614-2",⑥科目マッピング!$A:$F,4,0)/100,0)+IFERROR(VLOOKUP(D8,⑤売上原票!$A:$P,9,0)*VLOOKUP("614-3",⑥科目マッピング!$A:$F,4,0)/100,0)+IFERROR(VLOOKUP(D8,⑤売上原票!$A:$P,11,0)*VLOOKUP("615-2",⑥科目マッピング!$A:$F,4,0)/100,0)+IFERROR(VLOOKUP(D8,⑤売上原票!$A:$P,12,0)*VLOOKUP("615-3",⑥科目マッピング!$A:$F,4,0)/100,0)+IFERROR(VLOOKUP(D8,⑤売上原票!$A:$P,13,0)*VLOOKUP("615-4",⑥科目マッピング!$A:$F,4,0)/100,0) | I8: =E8+F8+G8+H8 | J8: 698000 | K8: 190000 | L8: 97000 | M8: 638000 | N8: 88000 | O8: 46000 | P8: 122000 | Q8: =J8+K8+L8+M8+N8+O8+P8 | R8: =I8-Q8 | S8: =IF(I8<>0,R8/I8,0) | T8: =IF(S8>=0.25,"◎ 優良",IF(S8>=0.15,"○ 良好",IF(S8>=0.05,"△ 要注意","× 赤字"))) | U8: =IF(I7<>0,I8/I7-1,"")
A9: C002 | B9: 都営地下鉄案件 | C9: 都営地下鉄 | D9: 2025-05 | E9: =IFERROR(VLOOKUP(D9,⑤売上原票!$A:$P,3,0)*VLOOKUP("612-1",⑥科目マッピング!$A:$F,5,0)/100,0) | F9: =IFERROR(VLOOKUP(D9,⑤売上原票!$A:$P,4,0)*VLOOKUP("612-2",⑥科目マッピング!$A:$F,5,0)/100,0) | G9: =IFERROR(VLOOKUP(D9,⑤売上原票!$A:$P,10,0)*VLOOKUP("615-1",⑥科目マッピング!$A:$F,5,0)/100,0) | H9: =IFERROR(VLOOKUP(D9,⑤売上原票!$A:$P,5,0)*VLOOKUP("613-1",⑥科目マッピング!$A:$F,5,0)/100,0)+IFERROR(VLOOKUP(D9,⑤売上原票!$A:$P,6,0)*VLOOKUP("613-2",⑥科目マッピング!$A:$F,5,0)/100,0)+IFERROR(VLOOKUP(D9,⑤売上原票!$A:$P,7,0)*VLOOKUP("614-1",⑥科目マッピング!$A:$F,5,0)/100,0)+IFERROR(VLOOKUP(D9,⑤売上原票!$A:$P,8,0)*VLOOKUP("614-2",⑥科目マッピング!$A:$F,5,0)/100,0)+IFERROR(VLOOKUP(D9,⑤売上原票!$A:$P,9,0)*VLOOKUP("614-3",⑥科目マッピング!$A:$F,5,0)/100,0)+IFERROR(VLOOKUP(D9,⑤売上原票!$A:$P,11,0)*VLOOKUP("615-2",⑥科目マッピング!$A:$F,5,0)/100,0)+IFERROR(VLOOKUP(D9,⑤売上原票!$A:$P,12,0)*VLOOKUP("615-3",⑥科目マッピング!$A:$F,5,0)/100,0)+IFERROR(VLOOKUP(D9,⑤売上原票!$A:$P,13,0)*VLOOKUP("615-4",⑥科目マッピング!$A:$F,5,0)/100,0) | I9: =E9+F9+G9+H9 | J9: 415000 | K9: 120000 | L9: 65000 | M9: 372000 | N9: 42000 | O9: 28000 | P9: 82000 | Q9: =J9+K9+L9+M9+N9+O9+P9 | R9: =I9-Q9 | S9: =IF(I9<>0,R9/I9,0) | T9: =IF(S9>=0.25,"◎ 優良",IF(S9>=0.15,"○ 良好",IF(S9>=0.05,"△ 要注意","× 赤字"))) | U9: —
A10: C002 | B10: 都営地下鉄案件 | C10: 都営地下鉄 | D10: 2025-06 | E10: =IFERROR(VLOOKUP(D10,⑤売上原票!$A:$P,3,0)*VLOOKUP("612-1",⑥科目マッピング!$A:$F,5,0)/100,0) | F10: =IFERROR(VLOOKUP(D10,⑤売上原票!$A:$P,4,0)*VLOOKUP("612-2",⑥科目マッピング!$A:$F,5,0)/100,0) | G10: =IFERROR(VLOOKUP(D10,⑤売上原票!$A:$P,10,0)*VLOOKUP("615-1",⑥科目マッピング!$A:$F,5,0)/100,0) | H10: =IFERROR(VLOOKUP(D10,⑤売上原票!$A:$P,5,0)*VLOOKUP("613-1",⑥科目マッピング!$A:$F,5,0)/100,0)+IFERROR(VLOOKUP(D10,⑤売上原票!$A:$P,6,0)*VLOOKUP("613-2",⑥科目マッピング!$A:$F,5,0)/100,0)+IFERROR(VLOOKUP(D10,⑤売上原票!$A:$P,7,0)*VLOOKUP("614-1",⑥科目マッピング!$A:$F,5,0)/100,0)+IFERROR(VLOOKUP(D10,⑤売上原票!$A:$P,8,0)*VLOOKUP("614-2",⑥科目マッピング!$A:$F,5,0)/100,0)+IFERROR(VLOOKUP(D10,⑤売上原票!$A:$P,9,0)*VLOOKUP("614-3",⑥科目マッピング!$A:$F,5,0)/100,0)+IFERROR(VLOOKUP(D10,⑤売上原票!$A:$P,11,0)*VLOOKUP("615-2",⑥科目マッピング!$A:$F,5,0)/100,0)+IFERROR(VLOOKUP(D10,⑤売上原票!$A:$P,12,0)*VLOOKUP("615-3",⑥科目マッピング!$A:$F,5,0)/100,0)+IFERROR(VLOOKUP(D10,⑤売上原票!$A:$P,13,0)*VLOOKUP("615-4",⑥科目マッピング!$A:$F,5,0)/100,0) | I10: =E10+F10+G10+H10 | J10: 428000 | K10: 128000 | L10: 68000 | M10: 385000 | N10: 44000 | O10: 30000 | P10: 88000 | Q10: =J10+K10+L10+M10+N10+O10+P10 | R10: =I10-Q10 | S10: =IF(I10<>0,R10/I10,0) | T10: =IF(S10>=0.25,"◎ 優良",IF(S10>=0.15,"○ 良好",IF(S10>=0.05,"△ 要注意","× 赤字"))) | U10: =IF(I9<>0,I10/I9-1,"")
A11: C002 | B11: 都営地下鉄案件 | C11: 都営地下鉄 | D11: 2025-07 | E11: =IFERROR(VLOOKUP(D11,⑤売上原票!$A:$P,3,0)*VLOOKUP("612-1",⑥科目マッピング!$A:$F,5,0)/100,0) | F11: =IFERROR(VLOOKUP(D11,⑤売上原票!$A:$P,4,0)*VLOOKUP("612-2",⑥科目マッピング!$A:$F,5,0)/100,0) | G11: =IFERROR(VLOOKUP(D11,⑤売上原票!$A:$P,10,0)*VLOOKUP("615-1",⑥科目マッピング!$A:$F,5,0)/100,0) | H11: =IFERROR(VLOOKUP(D11,⑤売上原票!$A:$P,5,0)*VLOOKUP("613-1",⑥科目マッピング!$A:$F,5,0)/100,0)+IFERROR(VLOOKUP(D11,⑤売上原票!$A:$P,6,0)*VLOOKUP("613-2",⑥科目マッピング!$A:$F,5,0)/100,0)+IFERROR(VLOOKUP(D11,⑤売上原票!$A:$P,7,0)*VLOOKUP("614-1",⑥科目マッピング!$A:$F,5,0)/100,0)+IFERROR(VLOOKUP(D11,⑤売上原票!$A:$P,8,0)*VLOOKUP("614-2",⑥科目マッピング!$A:$F,5,0)/100,0)+IFERROR(VLOOKUP(D11,⑤売上原票!$A:$P,9,0)*VLOOKUP("614-3",⑥科目マッピング!$A:$F,5,0)/100,0)+IFERROR(VLOOKUP(D11,⑤売上原票!$A:$P,11,0)*VLOOKUP("615-2",⑥科目マッピング!$A:$F,5,0)/100,0)+IFERROR(VLOOKUP(D11,⑤売上原票!$A:$P,12,0)*VLOOKUP("615-3",⑥科目マッピング!$A:$F,5,0)/100,0)+IFERROR(VLOOKUP(D11,⑤売上原票!$A:$P,13,0)*VLOOKUP("615-4",⑥科目マッピング!$A:$F,5,0)/100,0) | I11: =E11+F11+G11+H11 | J11: 445000 | K11: 135000 | L11: 72000 | M11: 405000 | N11: 46000 | O11: 32000 | P11: 92000 | Q11: =J11+K11+L11+M11+N11+O11+P11 | R11: =I11-Q11 | S11: =IF(I11<>0,R11/I11,0) | T11: =IF(S11>=0.25,"◎ 優良",IF(S11>=0.15,"○ 良好",IF(S11>=0.05,"△ 要注意","× 赤字"))) | U11: =IF(I10<>0,I11/I10-1,"")
A12: C002 | B12: 都営地下鉄案件 | C12: 都営地下鉄 | D12: 2025-08 | E12: =IFERROR(VLOOKUP(D12,⑤売上原票!$A:$P,3,0)*VLOOKUP("612-1",⑥科目マッピング!$A:$F,5,0)/100,0) | F12: =IFERROR(VLOOKUP(D12,⑤売上原票!$A:$P,4,0)*VLOOKUP("612-2",⑥科目マッピング!$A:$F,5,0)/100,0) | G12: =IFERROR(VLOOKUP(D12,⑤売上原票!$A:$P,10,0)*VLOOKUP("615-1",⑥科目マッピング!$A:$F,5,0)/100,0) | H12: =IFERROR(VLOOKUP(D12,⑤売上原票!$A:$P,5,0)*VLOOKUP("613-1",⑥科目マッピング!$A:$F,5,0)/100,0)+IFERROR(VLOOKUP(D12,⑤売上原票!$A:$P,6,0)*VLOOKUP("613-2",⑥科目マッピング!$A:$F,5,0)/100,0)+IFERROR(VLOOKUP(D12,⑤売上原票!$A:$P,7,0)*VLOOKUP("614-1",⑥科目マッピング!$A:$F,5,0)/100,0)+IFERROR(VLOOKUP(D12,⑤売上原票!$A:$P,8,0)*VLOOKUP("614-2",⑥科目マッピング!$A:$F,5,0)/100,0)+IFERROR(VLOOKUP(D12,⑤売上原票!$A:$P,9,0)*VLOOKUP("614-3",⑥科目マッピング!$A:$F,5,0)/100,0)+IFERROR(VLOOKUP(D12,⑤売上原票!$A:$P,11,0)*VLOOKUP("615-2",⑥科目マッピング!$A:$F,5,0)/100,0)+IFERROR(VLOOKUP(D12,⑤売上原票!$A:$P,12,0)*VLOOKUP("615-3",⑥科目マッピング!$A:$F,5,0)/100,0)+IFERROR(VLOOKUP(D12,⑤売上原票!$A:$P,13,0)*VLOOKUP("615-4",⑥科目マッピング!$A:$F,5,0)/100,0) | I12: =E12+F12+G12+H12 | J12: 438000 | K12: 130000 | L12: 70000 | M12: 395000 | N12: 44000 | O12: 31000 | P12: 90000 | Q12: =J12+K12+L12+M12+N12+O12+P12 | R12: =I12-Q12 | S12: =IF(I12<>0,R12/I12,0) | T12: =IF(S12>=0.25,"◎ 優良",IF(S12>=0.15,"○ 良好",IF(S12>=0.05,"△ 要注意","× 赤字"))) | U12: =IF(I11<>0,I12/I11-1,"")
A13: C003 | B13: 一般事業者案件 | C13: 一般事業者 | D13: 2025-05 | E13: =IFERROR(VLOOKUP(D13,⑤売上原票!$A:$P,3,0)*VLOOKUP("612-1",⑥科目マッピング!$A:$F,6,0)/100,0) | F13: =IFERROR(VLOOKUP(D13,⑤売上原票!$A:$P,4,0)*VLOOKUP("612-2",⑥科目マッピング!$A:$F,6,0)/100,0) | G13: =IFERROR(VLOOKUP(D13,⑤売上原票!$A:$P,10,0)*VLOOKUP("615-1",⑥科目マッピング!$A:$F,6,0)/100,0) | H13: =IFERROR(VLOOKUP(D13,⑤売上原票!$A:$P,5,0)*VLOOKUP("613-1",⑥科目マッピング!$A:$F,6,0)/100,0)+IFERROR(VLOOKUP(D13,⑤売上原票!$A:$P,6,0)*VLOOKUP("613-2",⑥科目マッピング!$A:$F,6,0)/100,0)+IFERROR(VLOOKUP(D13,⑤売上原票!$A:$P,7,0)*VLOOKUP("614-1",⑥科目マッピング!$A:$F,6,0)/100,0)+IFERROR(VLOOKUP(D13,⑤売上原票!$A:$P,8,0)*VLOOKUP("614-2",⑥科目マッピング!$A:$F,6,0)/100,0)+IFERROR(VLOOKUP(D13,⑤売上原票!$A:$P,9,0)*VLOOKUP("614-3",⑥科目マッピング!$A:$F,6,0)/100,0)+IFERROR(VLOOKUP(D13,⑤売上原票!$A:$P,11,0)*VLOOKUP("615-2",⑥科目マッピング!$A:$F,6,0)/100,0)+IFERROR(VLOOKUP(D13,⑤売上原票!$A:$P,12,0)*VLOOKUP("615-3",⑥科目マッピング!$A:$F,6,0)/100,0)+IFERROR(VLOOKUP(D13,⑤売上原票!$A:$P,13,0)*VLOOKUP("615-4",⑥科目マッピング!$A:$F,6,0)/100,0) | I13: =E13+F13+G13+H13 | J13: 1340000 | K13: 472000 | L13: 215000 | M13: 1155000 | N13: 160000 | O13: 82000 | P13: 205000 | Q13: =J13+K13+L13+M13+N13+O13+P13 | R13: =I13-Q13 | S13: =IF(I13<>0,R13/I13,0) | T13: =IF(S13>=0.25,"◎ 優良",IF(S13>=0.15,"○ 良好",IF(S13>=0.05,"△ 要注意","× 赤字"))) | U13: —
A14: C003 | B14: 一般事業者案件 | C14: 一般事業者 | D14: 2025-06 | E14: =IFERROR(VLOOKUP(D14,⑤売上原票!$A:$P,3,0)*VLOOKUP("612-1",⑥科目マッピング!$A:$F,6,0)/100,0) | F14: =IFERROR(VLOOKUP(D14,⑤売上原票!$A:$P,4,0)*VLOOKUP("612-2",⑥科目マッピング!$A:$F,6,0)/100,0) | G14: =IFERROR(VLOOKUP(D14,⑤売上原票!$A:$P,10,0)*VLOOKUP("615-1",⑥科目マッピング!$A:$F,6,0)/100,0) | H14: =IFERROR(VLOOKUP(D14,⑤売上原票!$A:$P,5,0)*VLOOKUP("613-1",⑥科目マッピング!$A:$F,6,0)/100,0)+IFERROR(VLOOKUP(D14,⑤売上原票!$A:$P,6,0)*VLOOKUP("613-2",⑥科目マッピング!$A:$F,6,0)/100,0)+IFERROR(VLOOKUP(D14,⑤売上原票!$A:$P,7,0)*VLOOKUP("614-1",⑥科目マッピング!$A:$F,6,0)/100,0)+IFERROR(VLOOKUP(D14,⑤売上原票!$A:$P,8,0)*VLOOKUP("614-2",⑥科目マッピング!$A:$F,6,0)/100,0)+IFERROR(VLOOKUP(D14,⑤売上原票!$A:$P,9,0)*VLOOKUP("614-3",⑥科目マッピング!$A:$F,6,0)/100,0)+IFERROR(VLOOKUP(D14,⑤売上原票!$A:$P,11,0)*VLOOKUP("615-2",⑥科目マッピング!$A:$F,6,0)/100,0)+IFERROR(VLOOKUP(D14,⑤売上原票!$A:$P,12,0)*VLOOKUP("615-3",⑥科目マッピング!$A:$F,6,0)/100,0)+IFERROR(VLOOKUP(D14,⑤売上原票!$A:$P,13,0)*VLOOKUP("615-4",⑥科目マッピング!$A:$F,6,0)/100,0) | I14: =E14+F14+G14+H14 | J14: 1365000 | K14: 502000 | L14: 228000 | M14: 1205000 | N14: 172000 | O14: 88000 | P14: 218000 | Q14: =J14+K14+L14+M14+N14+O14+P14 | R14: =I14-Q14 | S14: =IF(I14<>0,R14/I14,0) | T14: =IF(S14>=0.25,"◎ 優良",IF(S14>=0.15,"○ 良好",IF(S14>=0.05,"△ 要注意","× 赤字"))) | U14: =IF(I13<>0,I14/I13-1,"")
A15: C003 | B15: 一般事業者案件 | C15: 一般事業者 | D15: 2025-07 | E15: =IFERROR(VLOOKUP(D15,⑤売上原票!$A:$P,3,0)*VLOOKUP("612-1",⑥科目マッピング!$A:$F,6,0)/100,0) | F15: =IFERROR(VLOOKUP(D15,⑤売上原票!$A:$P,4,0)*VLOOKUP("612-2",⑥科目マッピング!$A:$F,6,0)/100,0) | G15: =IFERROR(VLOOKUP(D15,⑤売上原票!$A:$P,10,0)*VLOOKUP("615-1",⑥科目マッピング!$A:$F,6,0)/100,0) | H15: =IFERROR(VLOOKUP(D15,⑤売上原票!$A:$P,5,0)*VLOOKUP("613-1",⑥科目マッピング!$A:$F,6,0)/100,0)+IFERROR(VLOOKUP(D15,⑤売上原票!$A:$P,6,0)*VLOOKUP("613-2",⑥科目マッピング!$A:$F,6,0)/100,0)+IFERROR(VLOOKUP(D15,⑤売上原票!$A:$P,7,0)*VLOOKUP("614-1",⑥科目マッピング!$A:$F,6,0)/100,0)+IFERROR(VLOOKUP(D15,⑤売上原票!$A:$P,8,0)*VLOOKUP("614-2",⑥科目マッピング!$A:$F,6,0)/100,0)+IFERROR(VLOOKUP(D15,⑤売上原票!$A:$P,9,0)*VLOOKUP("614-3",⑥科目マッピング!$A:$F,6,0)/100,0)+IFERROR(VLOOKUP(D15,⑤売上原票!$A:$P,11,0)*VLOOKUP("615-2",⑥科目マッピング!$A:$F,6,0)/100,0)+IFERROR(VLOOKUP(D15,⑤売上原票!$A:$P,12,0)*VLOOKUP("615-3",⑥科目マッピング!$A:$F,6,0)/100,0)+IFERROR(VLOOKUP(D15,⑤売上原票!$A:$P,13,0)*VLOOKUP("615-4",⑥科目マッピング!$A:$F,6,0)/100,0) | I15: =E15+F15+G15+H15 | J15: 1410000 | K15: 530000 | L15: 238000 | M15: 1258000 | N15: 180000 | O15: 92000 | P15: 228000 | Q15: =J15+K15+L15+M15+N15+O15+P15 | R15: =I15-Q15 | S15: =IF(I15<>0,R15/I15,0) | T15: =IF(S15>=0.25,"◎ 優良",IF(S15>=0.15,"○ 良好",IF(S15>=0.05,"△ 要注意","× 赤字"))) | U15: =IF(I14<>0,I15/I14-1,"")
A16: C003 | B16: 一般事業者案件 | C16: 一般事業者 | D16: 2025-08 | E16: =IFERROR(VLOOKUP(D16,⑤売上原票!$A:$P,3,0)*VLOOKUP("612-1",⑥科目マッピング!$A:$F,6,0)/100,0) | F16: =IFERROR(VLOOKUP(D16,⑤売上原票!$A:$P,4,0)*VLOOKUP("612-2",⑥科目マッピング!$A:$F,6,0)/100,0) | G16: =IFERROR(VLOOKUP(D16,⑤売上原票!$A:$P,10,0)*VLOOKUP("615-1",⑥科目マッピング!$A:$F,6,0)/100,0) | H16: =IFERROR(VLOOKUP(D16,⑤売上原票!$A:$P,5,0)*VLOOKUP("613-1",⑥科目マッピング!$A:$F,6,0)/100,0)+IFERROR(VLOOKUP(D16,⑤売上原票!$A:$P,6,0)*VLOOKUP("613-2",⑥科目マッピング!$A:$F,6,0)/100,0)+IFERROR(VLOOKUP(D16,⑤売上原票!$A:$P,7,0)*VLOOKUP("614-1",⑥科目マッピング!$A:$F,6,0)/100,0)+IFERROR(VLOOKUP(D16,⑤売上原票!$A:$P,8,0)*VLOOKUP("614-2",⑥科目マッピング!$A:$F,6,0)/100,0)+IFERROR(VLOOKUP(D16,⑤売上原票!$A:$P,9,0)*VLOOKUP("614-3",⑥科目マッピング!$A:$F,6,0)/100,0)+IFERROR(VLOOKUP(D16,⑤売上原票!$A:$P,11,0)*VLOOKUP("615-2",⑥科目マッピング!$A:$F,6,0)/100,0)+IFERROR(VLOOKUP(D16,⑤売上原票!$A:$P,12,0)*VLOOKUP("615-3",⑥科目マッピング!$A:$F,6,0)/100,0)+IFERROR(VLOOKUP(D16,⑤売上原票!$A:$P,13,0)*VLOOKUP("615-4",⑥科目マッピング!$A:$F,6,0)/100,0) | I16: =E16+F16+G16+H16 | J16: 1395000 | K16: 515000 | L16: 232000 | M16: 1235000 | N16: 175000 | O16: 90000 | P16: 222000 | Q16: =J16+K16+L16+M16+N16+O16+P16 | R16: =I16-Q16 | S16: =IF(I16<>0,R16/I16,0) | T16: =IF(S16>=0.25,"◎ 優良",IF(S16>=0.15,"○ 良好",IF(S16>=0.05,"△ 要注意","× 赤字"))) | U16: =IF(I15<>0,I16/I15-1,"")
I17: =E17+F17+G17+H17 | Q17: =IF(J17+K17+L17+M17+N17+O17+P17=0,"",J17+K17+L17+M17+N17+O17+P17) | R17: =IF(OR(I17="",I17=0),"",I17-Q17) | S17: =IF(OR(I17="",I17=0),"",R17/I17) | T17: =IF(S17="","",IF(S17>=0.25,"◎ 優良",IF(S17>=0.15,"○ 良好",IF(S17>=0.05,"△ 要注意","× 赤字"))))
I18: =E18+F18+G18+H18 | Q18: =IF(J18+K18+L18+M18+N18+O18+P18=0,"",J18+K18+L18+M18+N18+O18+P18) | R18: =IF(OR(I18="",I18=0),"",I18-Q18) | S18: =IF(OR(I18="",I18=0),"",R18/I18) | T18: =IF(S18="","",IF(S18>=0.25,"◎ 優良",IF(S18>=0.15,"○ 良好",IF(S18>=0.05,"△ 要注意","× 赤字"))))
I19: =E19+F19+G19+H19 | Q19: =IF(J19+K19+L19+M19+N19+O19+P19=0,"",J19+K19+L19+M19+N19+O19+P19) | R19: =IF(OR(I19="",I19=0),"",I19-Q19) | S19: =IF(OR(I19="",I19=0),"",R19/I19) | T19: =IF(S19="","",IF(S19>=0.25,"◎ 優良",IF(S19>=0.15,"○ 良好",IF(S19>=0.05,"△ 要注意","× 赤字"))))
I20: =E20+F20+G20+H20 | Q20: =IF(J20+K20+L20+M20+N20+O20+P20=0,"",J20+K20+L20+M20+N20+O20+P20) | R20: =IF(OR(I20="",I20=0),"",I20-Q20) | S20: =IF(OR(I20="",I20=0),"",R20/I20) | T20: =IF(S20="","",IF(S20>=0.25,"◎ 優良",IF(S20>=0.15,"○ 良好",IF(S20>=0.05,"△ 要注意","× 赤字"))))
I21: =E21+F21+G21+H21 | Q21: =IF(J21+K21+L21+M21+N21+O21+P21=0,"",J21+K21+L21+M21+N21+O21+P21) | R21: =IF(OR(I21="",I21=0),"",I21-Q21) | S21: =IF(OR(I21="",I21=0),"",R21/I21) | T21: =IF(S21="","",IF(S21>=0.25,"◎ 優良",IF(S21>=0.15,"○ 良好",IF(S21>=0.05,"△ 要注意","× 赤字"))))
I22: =E22+F22+G22+H22 | Q22: =IF(J22+K22+L22+M22+N22+O22+P22=0,"",J22+K22+L22+M22+N22+O22+P22) | R22: =IF(OR(I22="",I22=0),"",I22-Q22) | S22: =IF(OR(I22="",I22=0),"",R22/I22) | T22: =IF(S22="","",IF(S22>=0.25,"◎ 優良",IF(S22>=0.15,"○ 良好",IF(S22>=0.05,"△ 要注意","× 赤字"))))
I23: =E23+F23+G23+H23 | Q23: =IF(J23+K23+L23+M23+N23+O23+P23=0,"",J23+K23+L23+M23+N23+O23+P23) | R23: =IF(OR(I23="",I23=0),"",I23-Q23) | S23: =IF(OR(I23="",I23=0),"",R23/I23) | T23: =IF(S23="","",IF(S23>=0.25,"◎ 優良",IF(S23>=0.15,"○ 良好",IF(S23>=0.05,"△ 要注意","× 赤字"))))
I24: =E24+F24+G24+H24 | Q24: =IF(J24+K24+L24+M24+N24+O24+P24=0,"",J24+K24+L24+M24+N24+O24+P24) | R24: =IF(OR(I24="",I24=0),"",I24-Q24) | S24: =IF(OR(I24="",I24=0),"",R24/I24) | T24: =IF(S24="","",IF(S24>=0.25,"◎ 優良",IF(S24>=0.15,"○ 良好",IF(S24>=0.05,"△ 要注意","× 赤字"))))
I25: =E25+F25+G25+H25 | Q25: =IF(J25+K25+L25+M25+N25+O25+P25=0,"",J25+K25+L25+M25+N25+O25+P25) | R25: =IF(OR(I25="",I25=0),"",I25-Q25) | S25: =IF(OR(I25="",I25=0),"",R25/I25) | T25: =IF(S25="","",IF(S25>=0.25,"◎ 優良",IF(S25>=0.15,"○ 良好",IF(S25>=0.05,"△ 要注意","× 赤字"))))
I26: =E26+F26+G26+H26 | Q26: =IF(J26+K26+L26+M26+N26+O26+P26=0,"",J26+K26+L26+M26+N26+O26+P26) | R26: =IF(OR(I26="",I26=0),"",I26-Q26) | S26: =IF(OR(I26="",I26=0),"",R26/I26) | T26: =IF(S26="","",IF(S26>=0.25,"◎ 優良",IF(S26>=0.15,"○ 良好",IF(S26>=0.05,"△ 要注意","× 赤字"))))
I27: =E27+F27+G27+H27 | Q27: =IF(J27+K27+L27+M27+N27+O27+P27=0,"",J27+K27+L27+M27+N27+O27+P27) | R27: =IF(OR(I27="",I27=0),"",I27-Q27) | S27: =IF(OR(I27="",I27=0),"",R27/I27) | T27: =IF(S27="","",IF(S27>=0.25,"◎ 優良",IF(S27>=0.15,"○ 良好",IF(S27>=0.05,"△ 要注意","× 赤字"))))
I28: =E28+F28+G28+H28 | Q28: =IF(J28+K28+L28+M28+N28+O28+P28=0,"",J28+K28+L28+M28+N28+O28+P28) | R28: =IF(OR(I28="",I28=0),"",I28-Q28) | S28: =IF(OR(I28="",I28=0),"",R28/I28) | T28: =IF(S28="","",IF(S28>=0.25,"◎ 優良",IF(S28>=0.15,"○ 良好",IF(S28>=0.05,"△ 要注意","× 赤字"))))
... I36: =E36+F36+G36+H36 | Q36: =IF(J36+K36+L36+M36+N36+O36+P36=0,"",J36+K36+L36+M36+N36+O36+P36) | R36: =IF(OR(I36="",I36=0),"",I36-Q36) | S36: =IF(OR(I36="",I36=0),"",R36/I36) | T36: =IF(S36="","",IF(S36>=0.25,"◎ 優良",IF(S36>=0.15,"○ 良好",IF(S36>=0.05,"△ 要注意","× 赤字"))))

Sheet ⑤売上原票
A1: 売上原票 月次実績（科目別・税抜） ※VLOOKUPキー列=A列(YYYY-MM)
A2: 【使い方】 ③月次採算入力の売上欄は =VLOOKUP(集計月, ⑤売上原票!$A:$P, 列番号, 0) で自動参照しています。毎月データを追記してください。
A3: VLOOKUP キー | C3: 科 目 別 売 上 (円・税抜) | N3: 合 計
A4: 年月 (VLOOKUPKEY) | B4: R表記 | C4: 612-1 運送（本社） | D4: 612-2 入札（公共） | E4: 613-1 車輌 | F4: 613-2 KC | G4: 614-1 コンテナ | H4: 614-2 ENDO | I4: 614-3 現金 | J4: 615-1 板橋 | K4: 615-2 新横浜 | L4: 615-3 現金2 | M4: 615-4 有価物 | N4: 合計 (税抜) | O4: 消費税 (△) | P4: 合計 (税込)
A5: 2024-07 | B5: R6.7 | C5: 13754437 | D5: 42726740 | E5: 777000 | F5: 40000 | G5: 504500 | H5: 527664 | I5: 261000 | J5: 25593317 | K5: 4417112 | L5: 36000 | M5: 138460 | N5: 88776230 | O5: -80705664 | P5: =IF(N5<>0,N5+O5,"")
A6: 2024-08 | B6: R6.8 | C6: 13060970 | D6: 36972090 | E6: 789000 | F6: 1000228 | G6: 507200 | H6: 518000 | J6: 20527297 | K6: 4953790 | L6: 57000 | M6: 172726 | N6: 78558301 | O6: -71416637 | P6: =IF(N6<>0,N6+O6,"")
A7: 2024-09 | B7: R6.9 | C7: 13837910 | D7: 37268605 | E7: 1143000 | G7: 513500 | H7: 480000 | J7: 22121458 | K7: 4072534 | L7: 54000 | M7: 162126 | N7: 79653133 | O7: -72411939 | P7: =IF(N7<>0,N7+O7,"")
A8: 2024-10 | B8: R6.10 | C8: 14538480 | D8: 39318469 | E8: 2859000 | F8: 3879338 | G8: 519500 | H8: 665902 | I8: 45000 | J8: 20930409 | K8: 4513589 | L8: 106000 | M8: 132040 | N8: 87507727 | O8: -79552479 | P8: =IF(N8<>0,N8+O8,"")
A9: 2024-11 | B9: R6.11 | C9: 12832260 | D9: 40166406 | E9: 891000 | F9: 2729582 | G9: 552500 | H9: 962040 | J9: 21039598 | K9: 4677613 | L9: 54000 | M9: 131610 | N9: 84036609 | O9: -76396917 | P9: =IF(N9<>0,N9+O9,"")
A10: 2024-12 | B10: R6.12 | C10: 13385794 | D10: 36230090 | E10: 885000 | F10: 3927473 | G10: 543500 | H10: 247700 | I10: 928500 | J10: 21774932 | K10: 4842835 | L10: 27000 | M10: 212926 | N10: 83005750 | O10: -75459773 | P10: =IF(N10<>0,N10+O10,"")
A11: 2025-01 | B11: R7.1 | C11: 11619926 | D11: 37239620 | F11: 1249028 | G11: 534500 | H11: 300000 | I11: 70000 | J11: 19408606 | K11: 4149715 | L11: 18000 | M11: 133330 | N11: 74722725 | O11: -67929750 | P11: =IF(N11<>0,N11+O11,"")
A12: 2025-02 | B12: R7.2 | C12: 12256849 | D12: 35273064 | E12: 716000 | G12: 534500 | H12: 150400 | J12: 18823147 | K12: 3791480 | L12: 75864 | M12: 163880 | N12: 71785184 | O12: -65259258 | P12: =IF(N12<>0,N12+O12,"")
A13: 2025-03 | B13: R7.3 | C13: 12036342 | D13: 39891431 | F13: 4399519 | G13: 534500 | H13: 35728 | I13: 177600 | J13: 21429591 | K13: 5604911 | L13: 73000 | M13: 167470 | N13: 84350092 | O13: -76681902 | P13: =IF(N13<>0,N13+O13,"")
A14: 2025-04 | B14: R7.4 | C14: 13732489 | D14: 42565460 | E14: 320000 | G14: 579000 | H14: 20000 | I14: 385190 | J14: 20293634 | K14: 4392253 | L14: 54000 | M14: 126695 | N14: 82468721 | O14: -74971565 | P14: =IF(N14<>0,N14+O14,"")
A15: 2025-05 | B15: R7.5 | C15: 12433945 | D15: 42621987 | E15: 24000 | G15: 399500 | H15: 375209 | I15: 4439900 | J15: 20536694 | K15: 4686122 | L15: 49068 | M15: 116600 | N15: 85683025 | O15: -77893659 | P15: =IF(N15<>0,N15+O15,"")
A16: 2025-06 | B16: R7.6 | C16: 12725923 | D16: 42039492 | E16: 560000 | F16: 6678437 | G16: 639500 | H16: 66155 | I16: 811380 | J16: 21382460 | K16: 4686956 | L16: 282934 | M16: 233890 | N16: 90107127 | O16: -81915570 | P16: =IF(N16<>0,N16+O16,"")
A17: 2025-07 | B17: R7.7 | C17: 14033460 | D17: 49551795 | E17: 70400 | G17: 439450 | H17: 522775 | I17: 3465 | J17: 24309231 | K17: 5799867 | L17: 19800 | M17: 299751 | N17: 95049994 | O17: -86409085 | P17: =IF(N17<>0,N17+O17,"")
A18: 2025-08 | B18: R7.8 | C18: 12775187 | D18: 45672694 | E18: 1859000 | F18: 6057720 | G18: 703450 | H18: 995236 | I18: 500 | J18: 21710565 | K18: 6235942 | L18: 85140 | M18: 297500 | N18: 96392934 | O18: -87629940 | P18: =IF(N18<>0,N18+O18,"")
N19: =IF(C19+D19+E19+F19+G19+H19+I19+J19+K19+L19+M19=0,"",C19+D19+E19+F19+G19+H19+I19+J19+K19+L19+M19) | O19: =IF(N19="","",ROUND(-N19/11,0)) | P19: =IF(N19="","",N19+O19)
N20: =IF(C20+D20+E20+F20+G20+H20+I20+J20+K20+L20+M20=0,"",C20+D20+E20+F20+G20+H20+I20+J20+K20+L20+M20) | O20: =IF(N20="","",ROUND(-N20/11,0)) | P20: =IF(N20="","",N20+O20)
N21: =IF(C21+D21+E21+F21+G21+H21+I21+J21+K21+L21+M21=0,"",C21+D21+E21+F21+G21+H21+I21+J21+K21+L21+M21) | O21: =IF(N21="","",ROUND(-N21/11,0)) | P21: =IF(N21="","",N21+O21)
N22: =IF(C22+D22+E22+F22+G22+H22+I22+J22+K22+L22+M22=0,"",C22+D22+E22+F22+G22+H22+I22+J22+K22+L22+M22) | O22: =IF(N22="","",ROUND(-N22/11,0)) | P22: =IF(N22="","",N22+O22)
N23: =IF(C23+D23+E23+F23+G23+H23+I23+J23+K23+L23+M23=0,"",C23+D23+E23+F23+G23+H23+I23+J23+K23+L23+M23) | O23: =IF(N23="","",ROUND(-N23/11,0)) | P23: =IF(N23="","",N23+O23)
N24: =IF(C24+D24+E24+F24+G24+H24+I24+J24+K24+L24+M24=0,"",C24+D24+E24+F24+G24+H24+I24+J24+K24+L24+M24) | O24: =IF(N24="","",ROUND(-N24/11,0)) | P24: =IF(N24="","",N24+O24)
N25: =IF(C25+D25+E25+F25+G25+H25+I25+J25+K25+L25+M25=0,"",C25+D25+E25+F25+G25+H25+I25+J25+K25+L25+M25) | O25: =IF(N25="","",ROUND(-N25/11,0)) | P25: =IF(N25="","",N25+O25)
N26: =IF(C26+D26+E26+F26+G26+H26+I26+J26+K26+L26+M26=0,"",C26+D26+E26+F26+G26+H26+I26+J26+K26+L26+M26) | O26: =IF(N26="","",ROUND(-N26/11,0)) | P26: =IF(N26="","",N26+O26)
N27: =IF(C27+D27+E27+F27+G27+H27+I27+J27+K27+L27+M27=0,"",C27+D27+E27+F27+G27+H27+I27+J27+K27+L27+M27) | O27: =IF(N27="","",ROUND(-N27/11,0)) | P27: =IF(N27="","",N27+O27)
N28: =IF(C28+D28+E28+F28+G28+H28+I28+J28+K28+L28+M28=0,"",C28+D28+E28+F28+G28+H28+I28+J28+K28+L28+M28) | O28: =IF(N28="","",ROUND(-N28/11,0)) | P28: =IF(N28="","",N28+O28)
N29: =IF(C29+D29+E29+F29+G29+H29+I29+J29+K29+L29+M29=0,"",C29+D29+E29+F29+G29+H29+I29+J29+K29+L29+M29) | O29: =IF(N29="","",ROUND(-N29/11,0)) | P29: =IF(N29="","",N29+O29)
N30: =IF(C30+D30+E30+F30+G30+H30+I30+J30+K30+L30+M30=0,"",C30+D30+E30+F30+G30+H30+I30+J30+K30+L30+M30) | O30: =IF(N30="","",ROUND(-N30/11,0)) | P30: =IF(N30="","",N30+O30)

Sheet ⑥科目-案件マッピング
A1: 科目-案件マッピング設定 ※配分率(%)を調整することで③採算入力の売上が変わります
A2: ★ C001/C002/C003 の合計が100%になるよう配分を設定してください（KCのみ別管理で0%可）
A3: 科目情報 | D3: 案件別配分率（%） | G3: 確認
A4: 科目コード | B4: 科目名 | C4: 性質 | D4: C001 東急グループ% | E4: C002 都営地下鉄% | F4: C003 一般事業者% | G4: 合計% (100が正常) | H4: 直近月売上 (参照) | I4: 直近月各案件 貢献額(参照)
A5: 612-1 | B5: 運送（本社） | C5: 民間運送 | D5: 0 | E5: 0 | F5: 100 | G5: =D5+E5+F5 | H5: =IFERROR(VLOOKUP(MAX(⑤売上原票!$A$5:$A$100),⑤売上原票!$A:$P,3,0),"-") | I5: =IF(H5="-","-",H5*(D5+E5+F5)/100)
A6: 612-2 | B6: 入札（公共） | C6: 公共入札 | D6: 0 | E6: 100 | F6: 0 | G6: =D6+E6+F6 | H6: =IFERROR(VLOOKUP(MAX(⑤売上原票!$A$5:$A$100),⑤売上原票!$A:$P,4,0),"-") | I6: =IF(H6="-","-",H6*(D6+E6+F6)/100)
A7: 613-1 | B7: 車輌 | C7: 車輌 | D7: 20 | E7: 10 | F7: 70 | G7: =D7+E7+F7 | H7: =IFERROR(VLOOKUP(MAX(⑤売上原票!$A$5:$A$100),⑤売上原票!$A:$P,5,0),"-") | I7: =IF(H7="-","-",H7*(D7+E7+F7)/100)
A8: 613-2 | B8: KC | C8: KC売上 | D8: 0 | E8: 0 | F8: 0 | G8: =D8+E8+F8 | H8: =IFERROR(VLOOKUP(MAX(⑤売上原票!$A$5:$A$100),⑤売上原票!$A:$P,6,0),"-") | I8: =IF(H8="-","-",H8*(D8+E8+F8)/100)
A9: 614-1 | B9: コンテナ | C9: コンテナ | D9: 0 | E9: 0 | F9: 100 | G9: =D9+E9+F9 | H9: =IFERROR(VLOOKUP(MAX(⑤売上原票!$A$5:$A$100),⑤売上原票!$A:$P,7,0),"-") | I9: =IF(H9="-","-",H9*(D9+E9+F9)/100)
A10: 614-2 | B10: ENDO | C10: ENDO | D10: 0 | E10: 0 | F10: 100 | G10: =D10+E10+F10 | H10: =IFERROR(VLOOKUP(MAX(⑤売上原票!$A$5:$A$100),⑤売上原票!$A:$P,8,0),"-") | I10: =IF(H10="-","-",H10*(D10+E10+F10)/100)
A11: 614-3 | B11: 現金 | C11: 現金 | D11: 0 | E11: 0 | F11: 100 | G11: =D11+E11+F11 | H11: =IFERROR(VLOOKUP(MAX(⑤売上原票!$A$5:$A$100),⑤売上原票!$A:$P,9,0),"-") | I11: =IF(H11="-","-",H11*(D11+E11+F11)/100)
A12: 615-1 | B12: 板橋 | C12: 板橋営業所 | D12: 60 | E12: 0 | F12: 40 | G12: =D12+E12+F12 | H12: =IFERROR(VLOOKUP(MAX(⑤売上原票!$A$5:$A$100),⑤売上原票!$A:$P,10,0),"-") | I12: =IF(H12="-","-",H12*(D12+E12+F12)/100)
A13: 615-2 | B13: 新横浜 | C13: 新横浜営業所 | D13: 0 | E13: 0 | F13: 100 | G13: =D13+E13+F13 | H13: =IFERROR(VLOOKUP(MAX(⑤売上原票!$A$5:$A$100),⑤売上原票!$A:$P,11,0),"-") | I13: =IF(H13="-","-",H13*(D13+E13+F13)/100)
A14: 615-3 | B14: 現金2 | C14: 現金2 | D14: 0 | E14: 0 | F14: 100 | G14: =D14+E14+F14 | H14: =IFERROR(VLOOKUP(MAX(⑤売上原票!$A$5:$A$100),⑤売上原票!$A:$P,12,0),"-") | I14: =IF(H14="-","-",H14*(D14+E14+F14)/100)
A15: 615-4 | B15: 有価物 | C15: 有価物 | D15: 0 | E15: 0 | F15: 100 | G15: =D15+E15+F15 | H15: =IFERROR(VLOOKUP(MAX(⑤売上原票!$A$5:$A$100),⑤売上原票!$A:$P,13,0),"-") | I15: =IF(H15="-","-",H15*(D15+E15+F15)/100)
A16: 合計 | D16: =SUM(D5:D15) | E16: =SUM(E5:E15) | F16: =SUM(F5:F15) | H16: =SUM(H5:H15) | I16: =SUM(I5:I15)
A18: 【配分の考え方の例】 615-1(板橋)：東急グループの拠点は板橋営業所担当のため東急60%・一般40%と設定。実際の売上構成に合わせて調整してください。

Sheet ⑦ドライバー別
A1: ドライバー別回収量サマリー
A2: ドライバー名 | B2: 担当拠点数 | C2: 週間回収量(kg) | D2: 月間回収量(kg推算) | E2: 1拠点あたり(kg) | F2: 備考
A3: 長谷川 | B3: 152 | C3: 12616 | D3: 50464 | E3: 83
A4: 長野 | B4: 96 | C4: 7850 | D4: 31400 | E4: 81.8
A5: 千葉 | B5: 242 | C5: 7472 | D5: 29888 | E5: 30.9
A6: 岡田 | B6: 60 | C6: 4128 | D6: 16512 | E6: 68.8
A7: 白 | B7: 16 | C7: 4120 | D7: 16480 | E7: 257.5
A8: 藤内 | B8: 29 | C8: 3775 | D8: 15100 | E8: 130.2
A9: 中條 | B9: 186 | C9: 3114 | D9: 12456 | E9: 16.7
A10: 宮原 | B10: 72 | C10: 2692 | D10: 10768 | E10: 37.4
A11: 大迫 | B11: 32 | C11: 2620 | D11: 10480 | E11: 81.9
A12: 鈴木 | B12: 9 | C12: 2401 | D12: 9604 | E12: 266.8
A13: 和田・荻野 | B13: 45 | C13: 771 | D13: 3084 | E13: 17.1
A14: 宮原・玉山 | B14: 17 | C14: 504 | D14: 2016 | E14: 29.6
... A16: 山口 | B16: 4 | C16: 340 | D16: 1360 | E16: 85

Sheet ⑧採算ダッシュボード
A1: 採算ダッシュボード
A3: ③月次採算入力の実績が蓄積されると、ここに集計が表示されます。現状は③シートをご参照ください。

Sheet ⑨換算テーブル
A1: 品目×袋サイズ 重量換算・CO₂係数テーブル
A2: 品目 | B2: 容器・サイズ | C2: 1単位あたり重量(kg) | D2: 備考 | E2: CO₂排出係数
A3: 品目 | B3: 容器・サイズ | C3: 1単位あたり重量(kg) | D3: 備考 | E3: CO₂排出係数(t-CO₂/t)
A4: 可燃ごみ | B4: 45Lポリ袋 | C4: 6 | D4: 飲食店の生ごみ含む場合は7-8kg | E4: 0.000352
A5: 可燃ごみ | B5: 70Lポリ袋 | C5: 10 | E5: 0.000352
A6: 可燃ごみ | B6: 90Lポリ袋 | C6: 13 | E6: 0.000352
A7: 可燃ごみ | B7: コンテナ（240L） | C7: 35 | D7: 駅構内の大型容器 | E7: 0.000352
A8: 不燃ごみ | B8: 45Lポリ袋 | C8: 8 | D8: 陶器・ガラス含む場合は重め | E8: 2.31e-05
A9: 不燃ごみ | B9: 70Lポリ袋 | C9: 13 | E9: 2.31e-05
A10: 段ボール | B10: 束（50cm角） | C10: 4 | D10: 厚み10cm程度 | E10: 3.69e-05
A11: 段ボール | B11: 束（50cm角・大） | C11: 8 | D11: 厚み20cm以上 | E11: 3.69e-05
A12: 瓶缶 | B12: 45Lポリ袋 | C12: 12 | D12: 瓶が多いと15kg程度 | E12: 2.31e-05
A13: 瓶缶 | B13: コンテナ（20L） | C13: 15 | D13: 金属缶中心 | E13: 2.31e-05
A14: 資源（紙類） | B14: 45Lポリ袋 | C14: 5 | D14: 新聞・雑誌 | E14: 3.69e-05
A15: 資源（紙類） | B15: 束（紐結束） | C15: 6 | D15: 段ボール以外の紙類 | E15: 3.69e-05
A16: ペットボトル | B16: 45Lポリ袋 | C16: 3 | D16: 圧縮なし | E16: 0.000183
A17: 汚泥 | B17: ドラム缶(200L) | C17: 200 | D17: 産廃・液状 | E17: 2.31e-05
A18: 廃プラスチック | B18: 45Lポリ袋 | C18: 4 | E18: 0.00272
A19: 木くず | B19: フレコンバッグ | C19: 300 | D19: 産廃 | E19: 0.000352
A23: ・上記の重量は目安です。拠点の特性に応じて実測値で補正してください。
A24: ・CO₂排出係数は環境省「サプライチェーンを通じた温室効果ガス排出量算定に関する排出原単位データベース」より引用
A25: ・台秤を設置した拠点では、換算値ではなく実測値を優先して使用してください。
