Workbook

Sheet 案件別採算
A1: 案件別 採算管理 （★黄色セル＝入力 緑セル＝自動計算）
A2: 【売上】⑤売上原票シートをVLOOKUPで参照（D列=集計月 YYYY-MM を入力すると自動セット） 【原価】黄色セルに毎月入力してください
A3: 案件ID | B3: 案件名 | C3: 集計月 (YYYY-MM) | D3: 売上（VLOOKUPで自動参照） | G3: その他 売上合計 | H3: 売上 合計 | I3: 原価 （黄色セルに入力） | P3: 原価 合計 | Q3: 粗利益 | R3: 粗利率 | S3: 採算 判定 | T3: 前月比 売上
D4: 運送 612-1 | E4: 入札 612-2 | F4: 板橋 615-1 | I4: 人件費 | J4: 燃料費 | K4: 車両 維持費 | L4: 中間 処理費 | M4: 搬入 運搬費 | N4: 電子M 代行費 | O4: 管理費
A5: C001 | B5: 東急グループ案件 | C5: 2024-07 | D5: =IFERROR(VLOOKUP(C5,▼売上原票!$A:$P,3,0)*VLOOKUP("612-1",▼マッピング!$A:$G,4,0)/100,0) | E5: =IFERROR(VLOOKUP(C5,▼売上原票!$A:$P,4,0)*VLOOKUP("612-2",▼マッピング!$A:$G,4,0)/100,0) | F5: =IFERROR(VLOOKUP(C5,▼売上原票!$A:$P,10,0)*VLOOKUP("615-1",▼マッピング!$A:$G,4,0)/100,0) | G5: =IFERROR(VLOOKUP(C5,▼売上原票!$A:$P,5,0)*VLOOKUP("613-1",▼マッピング!$A:$G,4,0)/100,0)+IFERROR(VLOOKUP(C5,▼売上原票!$A:$P,6,0)*VLOOKUP("613-2",▼マッピング!$A:$G,4,0)/100,0)+IFERROR(VLOOKUP(C5,▼売上原票!$A:$P,7,0)*VLOOKUP("614-1",▼マッピング!$A:$G,4,0)/100,0)+IFERROR(VLOOKUP(C5,▼売上原票!$A:$P,8,0)*VLOOKUP("614-2",▼マッピング!$A:$G,4,0)/100,0)+IFERROR(VLOOKUP(C5,▼売上原票!$A:$P,9,0)*VLOOKUP("614-3",▼マッピング!$A:$G,4,0)/100,0)+IFERROR(VLOOKUP(C5,▼売上原票!$A:$P,11,0)*VLOOKUP("615-2",▼マッピング!$A:$G,4,0)/100,0)+IFERROR(VLOOKUP(C5,▼売上原票!$A:$P,12,0)*VLOOKUP("615-3",▼マッピング!$A:$G,4,0)/100,0)+IFERROR(VLOOKUP(C5,▼売上原票!$A:$P,13,0)*VLOOKUP("615-4",▼マッピング!$A:$G,4,0)/100,0) | H5: =D5+E5+F5+G5 | P5: =I5+J5+K5+L5+M5+N5+O5 | Q5: =H5-P5 | R5: =IF(H5<>0,Q5/H5,0) | S5: =IF(R5>=0.25,"◎ 優良",IF(R5>=0.15,"○ 良好",IF(R5>=0.05,"△ 要注意","× 赤字"))) | T5: —
A6: C001 | B6: 東急グループ案件 | C6: 2024-08 | D6: =IFERROR(VLOOKUP(C6,▼売上原票!$A:$P,3,0)*VLOOKUP("612-1",▼マッピング!$A:$G,4,0)/100,0) | E6: =IFERROR(VLOOKUP(C6,▼売上原票!$A:$P,4,0)*VLOOKUP("612-2",▼マッピング!$A:$G,4,0)/100,0) | F6: =IFERROR(VLOOKUP(C6,▼売上原票!$A:$P,10,0)*VLOOKUP("615-1",▼マッピング!$A:$G,4,0)/100,0) | G6: =IFERROR(VLOOKUP(C6,▼売上原票!$A:$P,5,0)*VLOOKUP("613-1",▼マッピング!$A:$G,4,0)/100,0)+IFERROR(VLOOKUP(C6,▼売上原票!$A:$P,6,0)*VLOOKUP("613-2",▼マッピング!$A:$G,4,0)/100,0)+IFERROR(VLOOKUP(C6,▼売上原票!$A:$P,7,0)*VLOOKUP("614-1",▼マッピング!$A:$G,4,0)/100,0)+IFERROR(VLOOKUP(C6,▼売上原票!$A:$P,8,0)*VLOOKUP("614-2",▼マッピング!$A:$G,4,0)/100,0)+IFERROR(VLOOKUP(C6,▼売上原票!$A:$P,9,0)*VLOOKUP("614-3",▼マッピング!$A:$G,4,0)/100,0)+IFERROR(VLOOKUP(C6,▼売上原票!$A:$P,11,0)*VLOOKUP("615-2",▼マッピング!$A:$G,4,0)/100,0)+IFERROR(VLOOKUP(C6,▼売上原票!$A:$P,12,0)*VLOOKUP("615-3",▼マッピング!$A:$G,4,0)/100,0)+IFERROR(VLOOKUP(C6,▼売上原票!$A:$P,13,0)*VLOOKUP("615-4",▼マッピング!$A:$G,4,0)/100,0) | H6: =D6+E6+F6+G6 | P6: =I6+J6+K6+L6+M6+N6+O6 | Q6: =H6-P6 | R6: =IF(H6<>0,Q6/H6,0) | S6: =IF(R6>=0.25,"◎ 優良",IF(R6>=0.15,"○ 良好",IF(R6>=0.05,"△ 要注意","× 赤字"))) | T6: =IF(H5<>0,H6/H5-1,"")
A7: C001 | B7: 東急グループ案件 | C7: 2024-09 | D7: =IFERROR(VLOOKUP(C7,▼売上原票!$A:$P,3,0)*VLOOKUP("612-1",▼マッピング!$A:$G,4,0)/100,0) | E7: =IFERROR(VLOOKUP(C7,▼売上原票!$A:$P,4,0)*VLOOKUP("612-2",▼マッピング!$A:$G,4,0)/100,0) | F7: =IFERROR(VLOOKUP(C7,▼売上原票!$A:$P,10,0)*VLOOKUP("615-1",▼マッピング!$A:$G,4,0)/100,0) | G7: =IFERROR(VLOOKUP(C7,▼売上原票!$A:$P,5,0)*VLOOKUP("613-1",▼マッピング!$A:$G,4,0)/100,0)+IFERROR(VLOOKUP(C7,▼売上原票!$A:$P,6,0)*VLOOKUP("613-2",▼マッピング!$A:$G,4,0)/100,0)+IFERROR(VLOOKUP(C7,▼売上原票!$A:$P,7,0)*VLOOKUP("614-1",▼マッピング!$A:$G,4,0)/100,0)+IFERROR(VLOOKUP(C7,▼売上原票!$A:$P,8,0)*VLOOKUP("614-2",▼マッピング!$A:$G,4,0)/100,0)+IFERROR(VLOOKUP(C7,▼売上原票!$A:$P,9,0)*VLOOKUP("614-3",▼マッピング!$A:$G,4,0)/100,0)+IFERROR(VLOOKUP(C7,▼売上原票!$A:$P,11,0)*VLOOKUP("615-2",▼マッピング!$A:$G,4,0)/100,0)+IFERROR(VLOOKUP(C7,▼売上原票!$A:$P,12,0)*VLOOKUP("615-3",▼マッピング!$A:$G,4,0)/100,0)+IFERROR(VLOOKUP(C7,▼売上原票!$A:$P,13,0)*VLOOKUP("615-4",▼マッピング!$A:$G,4,0)/100,0) | H7: =D7+E7+F7+G7 | P7: =I7+J7+K7+L7+M7+N7+O7 | Q7: =H7-P7 | R7: =IF(H7<>0,Q7/H7,0) | S7: =IF(R7>=0.25,"◎ 優良",IF(R7>=0.15,"○ 良好",IF(R7>=0.05,"△ 要注意","× 赤字"))) | T7: =IF(H6<>0,H7/H6-1,"")
A8: C001 | B8: 東急グループ案件 | C8: 2024-10 | D8: =IFERROR(VLOOKUP(C8,▼売上原票!$A:$P,3,0)*VLOOKUP("612-1",▼マッピング!$A:$G,4,0)/100,0) | E8: =IFERROR(VLOOKUP(C8,▼売上原票!$A:$P,4,0)*VLOOKUP("612-2",▼マッピング!$A:$G,4,0)/100,0) | F8: =IFERROR(VLOOKUP(C8,▼売上原票!$A:$P,10,0)*VLOOKUP("615-1",▼マッピング!$A:$G,4,0)/100,0) | G8: =IFERROR(VLOOKUP(C8,▼売上原票!$A:$P,5,0)*VLOOKUP("613-1",▼マッピング!$A:$G,4,0)/100,0)+IFERROR(VLOOKUP(C8,▼売上原票!$A:$P,6,0)*VLOOKUP("613-2",▼マッピング!$A:$G,4,0)/100,0)+IFERROR(VLOOKUP(C8,▼売上原票!$A:$P,7,0)*VLOOKUP("614-1",▼マッピング!$A:$G,4,0)/100,0)+IFERROR(VLOOKUP(C8,▼売上原票!$A:$P,8,0)*VLOOKUP("614-2",▼マッピング!$A:$G,4,0)/100,0)+IFERROR(VLOOKUP(C8,▼売上原票!$A:$P,9,0)*VLOOKUP("614-3",▼マッピング!$A:$G,4,0)/100,0)+IFERROR(VLOOKUP(C8,▼売上原票!$A:$P,11,0)*VLOOKUP("615-2",▼マッピング!$A:$G,4,0)/100,0)+IFERROR(VLOOKUP(C8,▼売上原票!$A:$P,12,0)*VLOOKUP("615-3",▼マッピング!$A:$G,4,0)/100,0)+IFERROR(VLOOKUP(C8,▼売上原票!$A:$P,13,0)*VLOOKUP("615-4",▼マッピング!$A:$G,4,0)/100,0) | H8: =D8+E8+F8+G8 | P8: =I8+J8+K8+L8+M8+N8+O8 | Q8: =H8-P8 | R8: =IF(H8<>0,Q8/H8,0) | S8: =IF(R8>=0.25,"◎ 優良",IF(R8>=0.15,"○ 良好",IF(R8>=0.05,"△ 要注意","× 赤字"))) | T8: =IF(H7<>0,H8/H7-1,"")
A9: C001 | B9: 東急グループ案件 | C9: 2024-11 | D9: =IFERROR(VLOOKUP(C9,▼売上原票!$A:$P,3,0)*VLOOKUP("612-1",▼マッピング!$A:$G,4,0)/100,0) | E9: =IFERROR(VLOOKUP(C9,▼売上原票!$A:$P,4,0)*VLOOKUP("612-2",▼マッピング!$A:$G,4,0)/100,0) | F9: =IFERROR(VLOOKUP(C9,▼売上原票!$A:$P,10,0)*VLOOKUP("615-1",▼マッピング!$A:$G,4,0)/100,0) | G9: =IFERROR(VLOOKUP(C9,▼売上原票!$A:$P,5,0)*VLOOKUP("613-1",▼マッピング!$A:$G,4,0)/100,0)+IFERROR(VLOOKUP(C9,▼売上原票!$A:$P,6,0)*VLOOKUP("613-2",▼マッピング!$A:$G,4,0)/100,0)+IFERROR(VLOOKUP(C9,▼売上原票!$A:$P,7,0)*VLOOKUP("614-1",▼マッピング!$A:$G,4,0)/100,0)+IFERROR(VLOOKUP(C9,▼売上原票!$A:$P,8,0)*VLOOKUP("614-2",▼マッピング!$A:$G,4,0)/100,0)+IFERROR(VLOOKUP(C9,▼売上原票!$A:$P,9,0)*VLOOKUP("614-3",▼マッピング!$A:$G,4,0)/100,0)+IFERROR(VLOOKUP(C9,▼売上原票!$A:$P,11,0)*VLOOKUP("615-2",▼マッピング!$A:$G,4,0)/100,0)+IFERROR(VLOOKUP(C9,▼売上原票!$A:$P,12,0)*VLOOKUP("615-3",▼マッピング!$A:$G,4,0)/100,0)+IFERROR(VLOOKUP(C9,▼売上原票!$A:$P,13,0)*VLOOKUP("615-4",▼マッピング!$A:$G,4,0)/100,0) | H9: =D9+E9+F9+G9 | P9: =I9+J9+K9+L9+M9+N9+O9 | Q9: =H9-P9 | R9: =IF(H9<>0,Q9/H9,0) | S9: =IF(R9>=0.25,"◎ 優良",IF(R9>=0.15,"○ 良好",IF(R9>=0.05,"△ 要注意","× 赤字"))) | T9: =IF(H8<>0,H9/H8-1,"")
A10: C001 | B10: 東急グループ案件 | C10: 2024-12 | D10: =IFERROR(VLOOKUP(C10,▼売上原票!$A:$P,3,0)*VLOOKUP("612-1",▼マッピング!$A:$G,4,0)/100,0) | E10: =IFERROR(VLOOKUP(C10,▼売上原票!$A:$P,4,0)*VLOOKUP("612-2",▼マッピング!$A:$G,4,0)/100,0) | F10: =IFERROR(VLOOKUP(C10,▼売上原票!$A:$P,10,0)*VLOOKUP("615-1",▼マッピング!$A:$G,4,0)/100,0) | G10: =IFERROR(VLOOKUP(C10,▼売上原票!$A:$P,5,0)*VLOOKUP("613-1",▼マッピング!$A:$G,4,0)/100,0)+IFERROR(VLOOKUP(C10,▼売上原票!$A:$P,6,0)*VLOOKUP("613-2",▼マッピング!$A:$G,4,0)/100,0)+IFERROR(VLOOKUP(C10,▼売上原票!$A:$P,7,0)*VLOOKUP("614-1",▼マッピング!$A:$G,4,0)/100,0)+IFERROR(VLOOKUP(C10,▼売上原票!$A:$P,8,0)*VLOOKUP("614-2",▼マッピング!$A:$G,4,0)/100,0)+IFERROR(VLOOKUP(C10,▼売上原票!$A:$P,9,0)*VLOOKUP("614-3",▼マッピング!$A:$G,4,0)/100,0)+IFERROR(VLOOKUP(C10,▼売上原票!$A:$P,11,0)*VLOOKUP("615-2",▼マッピング!$A:$G,4,0)/100,0)+IFERROR(VLOOKUP(C10,▼売上原票!$A:$P,12,0)*VLOOKUP("615-3",▼マッピング!$A:$G,4,0)/100,0)+IFERROR(VLOOKUP(C10,▼売上原票!$A:$P,13,0)*VLOOKUP("615-4",▼マッピング!$A:$G,4,0)/100,0) | H10: =D10+E10+F10+G10 | P10: =I10+J10+K10+L10+M10+N10+O10 | Q10: =H10-P10 | R10: =IF(H10<>0,Q10/H10,0) | S10: =IF(R10>=0.25,"◎ 優良",IF(R10>=0.15,"○ 良好",IF(R10>=0.05,"△ 要注意","× 赤字"))) | T10: =IF(H9<>0,H10/H9-1,"")
A11: C001 | B11: 東急グループ案件 | C11: 2025-01 | D11: =IFERROR(VLOOKUP(C11,▼売上原票!$A:$P,3,0)*VLOOKUP("612-1",▼マッピング!$A:$G,4,0)/100,0) | E11: =IFERROR(VLOOKUP(C11,▼売上原票!$A:$P,4,0)*VLOOKUP("612-2",▼マッピング!$A:$G,4,0)/100,0) | F11: =IFERROR(VLOOKUP(C11,▼売上原票!$A:$P,10,0)*VLOOKUP("615-1",▼マッピング!$A:$G,4,0)/100,0) | G11: =IFERROR(VLOOKUP(C11,▼売上原票!$A:$P,5,0)*VLOOKUP("613-1",▼マッピング!$A:$G,4,0)/100,0)+IFERROR(VLOOKUP(C11,▼売上原票!$A:$P,6,0)*VLOOKUP("613-2",▼マッピング!$A:$G,4,0)/100,0)+IFERROR(VLOOKUP(C11,▼売上原票!$A:$P,7,0)*VLOOKUP("614-1",▼マッピング!$A:$G,4,0)/100,0)+IFERROR(VLOOKUP(C11,▼売上原票!$A:$P,8,0)*VLOOKUP("614-2",▼マッピング!$A:$G,4,0)/100,0)+IFERROR(VLOOKUP(C11,▼売上原票!$A:$P,9,0)*VLOOKUP("614-3",▼マッピング!$A:$G,4,0)/100,0)+IFERROR(VLOOKUP(C11,▼売上原票!$A:$P,11,0)*VLOOKUP("615-2",▼マッピング!$A:$G,4,0)/100,0)+IFERROR(VLOOKUP(C11,▼売上原票!$A:$P,12,0)*VLOOKUP("615-3",▼マッピング!$A:$G,4,0)/100,0)+IFERROR(VLOOKUP(C11,▼売上原票!$A:$P,13,0)*VLOOKUP("615-4",▼マッピング!$A:$G,4,0)/100,0) | H11: =D11+E11+F11+G11 | P11: =I11+J11+K11+L11+M11+N11+O11 | Q11: =H11-P11 | R11: =IF(H11<>0,Q11/H11,0) | S11: =IF(R11>=0.25,"◎ 優良",IF(R11>=0.15,"○ 良好",IF(R11>=0.05,"△ 要注意","× 赤字"))) | T11: =IF(H10<>0,H11/H10-1,"")
A12: C001 | B12: 東急グループ案件 | C12: 2025-02 | D12: =IFERROR(VLOOKUP(C12,▼売上原票!$A:$P,3,0)*VLOOKUP("612-1",▼マッピング!$A:$G,4,0)/100,0) | E12: =IFERROR(VLOOKUP(C12,▼売上原票!$A:$P,4,0)*VLOOKUP("612-2",▼マッピング!$A:$G,4,0)/100,0) | F12: =IFERROR(VLOOKUP(C12,▼売上原票!$A:$P,10,0)*VLOOKUP("615-1",▼マッピング!$A:$G,4,0)/100,0) | G12: =IFERROR(VLOOKUP(C12,▼売上原票!$A:$P,5,0)*VLOOKUP("613-1",▼マッピング!$A:$G,4,0)/100,0)+IFERROR(VLOOKUP(C12,▼売上原票!$A:$P,6,0)*VLOOKUP("613-2",▼マッピング!$A:$G,4,0)/100,0)+IFERROR(VLOOKUP(C12,▼売上原票!$A:$P,7,0)*VLOOKUP("614-1",▼マッピング!$A:$G,4,0)/100,0)+IFERROR(VLOOKUP(C12,▼売上原票!$A:$P,8,0)*VLOOKUP("614-2",▼マッピング!$A:$G,4,0)/100,0)+IFERROR(VLOOKUP(C12,▼売上原票!$A:$P,9,0)*VLOOKUP("614-3",▼マッピング!$A:$G,4,0)/100,0)+IFERROR(VLOOKUP(C12,▼売上原票!$A:$P,11,0)*VLOOKUP("615-2",▼マッピング!$A:$G,4,0)/100,0)+IFERROR(VLOOKUP(C12,▼売上原票!$A:$P,12,0)*VLOOKUP("615-3",▼マッピング!$A:$G,4,0)/100,0)+IFERROR(VLOOKUP(C12,▼売上原票!$A:$P,13,0)*VLOOKUP("615-4",▼マッピング!$A:$G,4,0)/100,0) | H12: =D12+E12+F12+G12 | P12: =I12+J12+K12+L12+M12+N12+O12 | Q12: =H12-P12 | R12: =IF(H12<>0,Q12/H12,0) | S12: =IF(R12>=0.25,"◎ 優良",IF(R12>=0.15,"○ 良好",IF(R12>=0.05,"△ 要注意","× 赤字"))) | T12: =IF(H11<>0,H12/H11-1,"")
A13: C001 | B13: 東急グループ案件 | C13: 2025-03 | D13: =IFERROR(VLOOKUP(C13,▼売上原票!$A:$P,3,0)*VLOOKUP("612-1",▼マッピング!$A:$G,4,0)/100,0) | E13: =IFERROR(VLOOKUP(C13,▼売上原票!$A:$P,4,0)*VLOOKUP("612-2",▼マッピング!$A:$G,4,0)/100,0) | F13: =IFERROR(VLOOKUP(C13,▼売上原票!$A:$P,10,0)*VLOOKUP("615-1",▼マッピング!$A:$G,4,0)/100,0) | G13: =IFERROR(VLOOKUP(C13,▼売上原票!$A:$P,5,0)*VLOOKUP("613-1",▼マッピング!$A:$G,4,0)/100,0)+IFERROR(VLOOKUP(C13,▼売上原票!$A:$P,6,0)*VLOOKUP("613-2",▼マッピング!$A:$G,4,0)/100,0)+IFERROR(VLOOKUP(C13,▼売上原票!$A:$P,7,0)*VLOOKUP("614-1",▼マッピング!$A:$G,4,0)/100,0)+IFERROR(VLOOKUP(C13,▼売上原票!$A:$P,8,0)*VLOOKUP("614-2",▼マッピング!$A:$G,4,0)/100,0)+IFERROR(VLOOKUP(C13,▼売上原票!$A:$P,9,0)*VLOOKUP("614-3",▼マッピング!$A:$G,4,0)/100,0)+IFERROR(VLOOKUP(C13,▼売上原票!$A:$P,11,0)*VLOOKUP("615-2",▼マッピング!$A:$G,4,0)/100,0)+IFERROR(VLOOKUP(C13,▼売上原票!$A:$P,12,0)*VLOOKUP("615-3",▼マッピング!$A:$G,4,0)/100,0)+IFERROR(VLOOKUP(C13,▼売上原票!$A:$P,13,0)*VLOOKUP("615-4",▼マッピング!$A:$G,4,0)/100,0) | H13: =D13+E13+F13+G13 | P13: =I13+J13+K13+L13+M13+N13+O13 | Q13: =H13-P13 | R13: =IF(H13<>0,Q13/H13,0) | S13: =IF(R13>=0.25,"◎ 優良",IF(R13>=0.15,"○ 良好",IF(R13>=0.05,"△ 要注意","× 赤字"))) | T13: =IF(H12<>0,H13/H12-1,"")
A14: C001 | B14: 東急グループ案件 | C14: 2025-04 | D14: =IFERROR(VLOOKUP(C14,▼売上原票!$A:$P,3,0)*VLOOKUP("612-1",▼マッピング!$A:$G,4,0)/100,0) | E14: =IFERROR(VLOOKUP(C14,▼売上原票!$A:$P,4,0)*VLOOKUP("612-2",▼マッピング!$A:$G,4,0)/100,0) | F14: =IFERROR(VLOOKUP(C14,▼売上原票!$A:$P,10,0)*VLOOKUP("615-1",▼マッピング!$A:$G,4,0)/100,0) | G14: =IFERROR(VLOOKUP(C14,▼売上原票!$A:$P,5,0)*VLOOKUP("613-1",▼マッピング!$A:$G,4,0)/100,0)+IFERROR(VLOOKUP(C14,▼売上原票!$A:$P,6,0)*VLOOKUP("613-2",▼マッピング!$A:$G,4,0)/100,0)+IFERROR(VLOOKUP(C14,▼売上原票!$A:$P,7,0)*VLOOKUP("614-1",▼マッピング!$A:$G,4,0)/100,0)+IFERROR(VLOOKUP(C14,▼売上原票!$A:$P,8,0)*VLOOKUP("614-2",▼マッピング!$A:$G,4,0)/100,0)+IFERROR(VLOOKUP(C14,▼売上原票!$A:$P,9,0)*VLOOKUP("614-3",▼マッピング!$A:$G,4,0)/100,0)+IFERROR(VLOOKUP(C14,▼売上原票!$A:$P,11,0)*VLOOKUP("615-2",▼マッピング!$A:$G,4,0)/100,0)+IFERROR(VLOOKUP(C14,▼売上原票!$A:$P,12,0)*VLOOKUP("615-3",▼マッピング!$A:$G,4,0)/100,0)+IFERROR(VLOOKUP(C14,▼売上原票!$A:$P,13,0)*VLOOKUP("615-4",▼マッピング!$A:$G,4,0)/100,0) | H14: =D14+E14+F14+G14 | P14: =I14+J14+K14+L14+M14+N14+O14 | Q14: =H14-P14 | R14: =IF(H14<>0,Q14/H14,0) | S14: =IF(R14>=0.25,"◎ 優良",IF(R14>=0.15,"○ 良好",IF(R14>=0.05,"△ 要注意","× 赤字"))) | T14: =IF(H13<>0,H14/H13-1,"")
A15: C001 | B15: 東急グループ案件 | C15: 2025-05 | D15: =IFERROR(VLOOKUP(C15,▼売上原票!$A:$P,3,0)*VLOOKUP("612-1",▼マッピング!$A:$G,4,0)/100,0) | E15: =IFERROR(VLOOKUP(C15,▼売上原票!$A:$P,4,0)*VLOOKUP("612-2",▼マッピング!$A:$G,4,0)/100,0) | F15: =IFERROR(VLOOKUP(C15,▼売上原票!$A:$P,10,0)*VLOOKUP("615-1",▼マッピング!$A:$G,4,0)/100,0) | G15: =IFERROR(VLOOKUP(C15,▼売上原票!$A:$P,5,0)*VLOOKUP("613-1",▼マッピング!$A:$G,4,0)/100,0)+IFERROR(VLOOKUP(C15,▼売上原票!$A:$P,6,0)*VLOOKUP("613-2",▼マッピング!$A:$G,4,0)/100,0)+IFERROR(VLOOKUP(C15,▼売上原票!$A:$P,7,0)*VLOOKUP("614-1",▼マッピング!$A:$G,4,0)/100,0)+IFERROR(VLOOKUP(C15,▼売上原票!$A:$P,8,0)*VLOOKUP("614-2",▼マッピング!$A:$G,4,0)/100,0)+IFERROR(VLOOKUP(C15,▼売上原票!$A:$P,9,0)*VLOOKUP("614-3",▼マッピング!$A:$G,4,0)/100,0)+IFERROR(VLOOKUP(C15,▼売上原票!$A:$P,11,0)*VLOOKUP("615-2",▼マッピング!$A:$G,4,0)/100,0)+IFERROR(VLOOKUP(C15,▼売上原票!$A:$P,12,0)*VLOOKUP("615-3",▼マッピング!$A:$G,4,0)/100,0)+IFERROR(VLOOKUP(C15,▼売上原票!$A:$P,13,0)*VLOOKUP("615-4",▼マッピング!$A:$G,4,0)/100,0) | H15: =D15+E15+F15+G15 | P15: =I15+J15+K15+L15+M15+N15+O15 | Q15: =H15-P15 | R15: =IF(H15<>0,Q15/H15,0) | S15: =IF(R15>=0.25,"◎ 優良",IF(R15>=0.15,"○ 良好",IF(R15>=0.05,"△ 要注意","× 赤字"))) | T15: =IF(H14<>0,H15/H14-1,"")
A16: C001 | B16: 東急グループ案件 | C16: 2025-06 | D16: =IFERROR(VLOOKUP(C16,▼売上原票!$A:$P,3,0)*VLOOKUP("612-1",▼マッピング!$A:$G,4,0)/100,0) | E16: =IFERROR(VLOOKUP(C16,▼売上原票!$A:$P,4,0)*VLOOKUP("612-2",▼マッピング!$A:$G,4,0)/100,0) | F16: =IFERROR(VLOOKUP(C16,▼売上原票!$A:$P,10,0)*VLOOKUP("615-1",▼マッピング!$A:$G,4,0)/100,0) | G16: =IFERROR(VLOOKUP(C16,▼売上原票!$A:$P,5,0)*VLOOKUP("613-1",▼マッピング!$A:$G,4,0)/100,0)+IFERROR(VLOOKUP(C16,▼売上原票!$A:$P,6,0)*VLOOKUP("613-2",▼マッピング!$A:$G,4,0)/100,0)+IFERROR(VLOOKUP(C16,▼売上原票!$A:$P,7,0)*VLOOKUP("614-1",▼マッピング!$A:$G,4,0)/100,0)+IFERROR(VLOOKUP(C16,▼売上原票!$A:$P,8,0)*VLOOKUP("614-2",▼マッピング!$A:$G,4,0)/100,0)+IFERROR(VLOOKUP(C16,▼売上原票!$A:$P,9,0)*VLOOKUP("614-3",▼マッピング!$A:$G,4,0)/100,0)+IFERROR(VLOOKUP(C16,▼売上原票!$A:$P,11,0)*VLOOKUP("615-2",▼マッピング!$A:$G,4,0)/100,0)+IFERROR(VLOOKUP(C16,▼売上原票!$A:$P,12,0)*VLOOKUP("615-3",▼マッピング!$A:$G,4,0)/100,0)+IFERROR(VLOOKUP(C16,▼売上原票!$A:$P,13,0)*VLOOKUP("615-4",▼マッピング!$A:$G,4,0)/100,0) | H16: =D16+E16+F16+G16 | P16: =I16+J16+K16+L16+M16+N16+O16 | Q16: =H16-P16 | R16: =IF(H16<>0,Q16/H16,0) | S16: =IF(R16>=0.25,"◎ 優良",IF(R16>=0.15,"○ 良好",IF(R16>=0.05,"△ 要注意","× 赤字"))) | T16: =IF(H15<>0,H16/H15-1,"")
A17: C001 | B17: 東急グループ案件 | C17: 2025-07 | D17: =IFERROR(VLOOKUP(C17,▼売上原票!$A:$P,3,0)*VLOOKUP("612-1",▼マッピング!$A:$G,4,0)/100,0) | E17: =IFERROR(VLOOKUP(C17,▼売上原票!$A:$P,4,0)*VLOOKUP("612-2",▼マッピング!$A:$G,4,0)/100,0) | F17: =IFERROR(VLOOKUP(C17,▼売上原票!$A:$P,10,0)*VLOOKUP("615-1",▼マッピング!$A:$G,4,0)/100,0) | G17: =IFERROR(VLOOKUP(C17,▼売上原票!$A:$P,5,0)*VLOOKUP("613-1",▼マッピング!$A:$G,4,0)/100,0)+IFERROR(VLOOKUP(C17,▼売上原票!$A:$P,6,0)*VLOOKUP("613-2",▼マッピング!$A:$G,4,0)/100,0)+IFERROR(VLOOKUP(C17,▼売上原票!$A:$P,7,0)*VLOOKUP("614-1",▼マッピング!$A:$G,4,0)/100,0)+IFERROR(VLOOKUP(C17,▼売上原票!$A:$P,8,0)*VLOOKUP("614-2",▼マッピング!$A:$G,4,0)/100,0)+IFERROR(VLOOKUP(C17,▼売上原票!$A:$P,9,0)*VLOOKUP("614-3",▼マッピング!$A:$G,4,0)/100,0)+IFERROR(VLOOKUP(C17,▼売上原票!$A:$P,11,0)*VLOOKUP("615-2",▼マッピング!$A:$G,4,0)/100,0)+IFERROR(VLOOKUP(C17,▼売上原票!$A:$P,12,0)*VLOOKUP("615-3",▼マッピング!$A:$G,4,0)/100,0)+IFERROR(VLOOKUP(C17,▼売上原票!$A:$P,13,0)*VLOOKUP("615-4",▼マッピング!$A:$G,4,0)/100,0) | H17: =D17+E17+F17+G17 | P17: =I17+J17+K17+L17+M17+N17+O17 | Q17: =H17-P17 | R17: =IF(H17<>0,Q17/H17,0) | S17: =IF(R17>=0.25,"◎ 優良",IF(R17>=0.15,"○ 良好",IF(R17>=0.05,"△ 要注意","× 赤字"))) | T17: =IF(H16<>0,H17/H16-1,"")
... A21: C001 | B21: 東急グループ案件 | C21: 2025-11 | D21: =IFERROR(VLOOKUP(C21,▼売上原票!$A:$P,3,0)*VLOOKUP("612-1",▼マッピング!$A:$G,4,0)/100,0) | E21: =IFERROR(VLOOKUP(C21,▼売上原票!$A:$P,4,0)*VLOOKUP("612-2",▼マッピング!$A:$G,4,0)/100,0) | F21: =IFERROR(VLOOKUP(C21,▼売上原票!$A:$P,10,0)*VLOOKUP("615-1",▼マッピング!$A:$G,4,0)/100,0) | G21: =IFERROR(VLOOKUP(C21,▼売上原票!$A:$P,5,0)*VLOOKUP("613-1",▼マッピング!$A:$G,4,0)/100,0)+IFERROR(VLOOKUP(C21,▼売上原票!$A:$P,6,0)*VLOOKUP("613-2",▼マッピング!$A:$G,4,0)/100,0)+IFERROR(VLOOKUP(C21,▼売上原票!$A:$P,7,0)*VLOOKUP("614-1",▼マッピング!$A:$G,4,0)/100,0)+IFERROR(VLOOKUP(C21,▼売上原票!$A:$P,8,0)*VLOOKUP("614-2",▼マッピング!$A:$G,4,0)/100,0)+IFERROR(VLOOKUP(C21,▼売上原票!$A:$P,9,0)*VLOOKUP("614-3",▼マッピング!$A:$G,4,0)/100,0)+IFERROR(VLOOKUP(C21,▼売上原票!$A:$P,11,0)*VLOOKUP("615-2",▼マッピング!$A:$G,4,0)/100,0)+IFERROR(VLOOKUP(C21,▼売上原票!$A:$P,12,0)*VLOOKUP("615-3",▼マッピング!$A:$G,4,0)/100,0)+IFERROR(VLOOKUP(C21,▼売上原票!$A:$P,13,0)*VLOOKUP("615-4",▼マッピング!$A:$G,4,0)/100,0) | H21: =D21+E21+F21+G21 | P21: =I21+J21+K21+L21+M21+N21+O21 | Q21: =H21-P21 | R21: =IF(H21<>0,Q21/H21,0) | S21: =IF(R21>=0.25,"◎ 優良",IF(R21>=0.15,"○ 良好",IF(R21>=0.05,"△ 要注意","× 赤字"))) | T21: =IF(H20<>0,H21/H20-1,"")
A23: C002 | B23: 都営地下鉄案件 | C23: 2024-07 | D23: =IFERROR(VLOOKUP(C23,▼売上原票!$A:$P,3,0)*VLOOKUP("612-1",▼マッピング!$A:$G,5,0)/100,0) | E23: =IFERROR(VLOOKUP(C23,▼売上原票!$A:$P,4,0)*VLOOKUP("612-2",▼マッピング!$A:$G,5,0)/100,0) | F23: =IFERROR(VLOOKUP(C23,▼売上原票!$A:$P,10,0)*VLOOKUP("615-1",▼マッピング!$A:$G,5,0)/100,0) | G23: =IFERROR(VLOOKUP(C23,▼売上原票!$A:$P,5,0)*VLOOKUP("613-1",▼マッピング!$A:$G,5,0)/100,0)+IFERROR(VLOOKUP(C23,▼売上原票!$A:$P,6,0)*VLOOKUP("613-2",▼マッピング!$A:$G,5,0)/100,0)+IFERROR(VLOOKUP(C23,▼売上原票!$A:$P,7,0)*VLOOKUP("614-1",▼マッピング!$A:$G,5,0)/100,0)+IFERROR(VLOOKUP(C23,▼売上原票!$A:$P,8,0)*VLOOKUP("614-2",▼マッピング!$A:$G,5,0)/100,0)+IFERROR(VLOOKUP(C23,▼売上原票!$A:$P,9,0)*VLOOKUP("614-3",▼マッピング!$A:$G,5,0)/100,0)+IFERROR(VLOOKUP(C23,▼売上原票!$A:$P,11,0)*VLOOKUP("615-2",▼マッピング!$A:$G,5,0)/100,0)+IFERROR(VLOOKUP(C23,▼売上原票!$A:$P,12,0)*VLOOKUP("615-3",▼マッピング!$A:$G,5,0)/100,0)+IFERROR(VLOOKUP(C23,▼売上原票!$A:$P,13,0)*VLOOKUP("615-4",▼マッピング!$A:$G,5,0)/100,0) | H23: =D23+E23+F23+G23 | P23: =I23+J23+K23+L23+M23+N23+O23 | Q23: =H23-P23 | R23: =IF(H23<>0,Q23/H23,0) | S23: =IF(R23>=0.25,"◎ 優良",IF(R23>=0.15,"○ 良好",IF(R23>=0.05,"△ 要注意","× 赤字"))) | T23: —
A24: C002 | B24: 都営地下鉄案件 | C24: 2024-08 | D24: =IFERROR(VLOOKUP(C24,▼売上原票!$A:$P,3,0)*VLOOKUP("612-1",▼マッピング!$A:$G,5,0)/100,0) | E24: =IFERROR(VLOOKUP(C24,▼売上原票!$A:$P,4,0)*VLOOKUP("612-2",▼マッピング!$A:$G,5,0)/100,0) | F24: =IFERROR(VLOOKUP(C24,▼売上原票!$A:$P,10,0)*VLOOKUP("615-1",▼マッピング!$A:$G,5,0)/100,0) | G24: =IFERROR(VLOOKUP(C24,▼売上原票!$A:$P,5,0)*VLOOKUP("613-1",▼マッピング!$A:$G,5,0)/100,0)+IFERROR(VLOOKUP(C24,▼売上原票!$A:$P,6,0)*VLOOKUP("613-2",▼マッピング!$A:$G,5,0)/100,0)+IFERROR(VLOOKUP(C24,▼売上原票!$A:$P,7,0)*VLOOKUP("614-1",▼マッピング!$A:$G,5,0)/100,0)+IFERROR(VLOOKUP(C24,▼売上原票!$A:$P,8,0)*VLOOKUP("614-2",▼マッピング!$A:$G,5,0)/100,0)+IFERROR(VLOOKUP(C24,▼売上原票!$A:$P,9,0)*VLOOKUP("614-3",▼マッピング!$A:$G,5,0)/100,0)+IFERROR(VLOOKUP(C24,▼売上原票!$A:$P,11,0)*VLOOKUP("615-2",▼マッピング!$A:$G,5,0)/100,0)+IFERROR(VLOOKUP(C24,▼売上原票!$A:$P,12,0)*VLOOKUP("615-3",▼マッピング!$A:$G,5,0)/100,0)+IFERROR(VLOOKUP(C24,▼売上原票!$A:$P,13,0)*VLOOKUP("615-4",▼マッピング!$A:$G,5,0)/100,0) | H24: =D24+E24+F24+G24 | P24: =I24+J24+K24+L24+M24+N24+O24 | Q24: =H24-P24 | R24: =IF(H24<>0,Q24/H24,0) | S24: =IF(R24>=0.25,"◎ 優良",IF(R24>=0.15,"○ 良好",IF(R24>=0.05,"△ 要注意","× 赤字"))) | T24: =IF(H23<>0,H24/H23-1,"")
A25: C002 | B25: 都営地下鉄案件 | C25: 2024-09 | D25: =IFERROR(VLOOKUP(C25,▼売上原票!$A:$P,3,0)*VLOOKUP("612-1",▼マッピング!$A:$G,5,0)/100,0) | E25: =IFERROR(VLOOKUP(C25,▼売上原票!$A:$P,4,0)*VLOOKUP("612-2",▼マッピング!$A:$G,5,0)/100,0) | F25: =IFERROR(VLOOKUP(C25,▼売上原票!$A:$P,10,0)*VLOOKUP("615-1",▼マッピング!$A:$G,5,0)/100,0) | G25: =IFERROR(VLOOKUP(C25,▼売上原票!$A:$P,5,0)*VLOOKUP("613-1",▼マッピング!$A:$G,5,0)/100,0)+IFERROR(VLOOKUP(C25,▼売上原票!$A:$P,6,0)*VLOOKUP("613-2",▼マッピング!$A:$G,5,0)/100,0)+IFERROR(VLOOKUP(C25,▼売上原票!$A:$P,7,0)*VLOOKUP("614-1",▼マッピング!$A:$G,5,0)/100,0)+IFERROR(VLOOKUP(C25,▼売上原票!$A:$P,8,0)*VLOOKUP("614-2",▼マッピング!$A:$G,5,0)/100,0)+IFERROR(VLOOKUP(C25,▼売上原票!$A:$P,9,0)*VLOOKUP("614-3",▼マッピング!$A:$G,5,0)/100,0)+IFERROR(VLOOKUP(C25,▼売上原票!$A:$P,11,0)*VLOOKUP("615-2",▼マッピング!$A:$G,5,0)/100,0)+IFERROR(VLOOKUP(C25,▼売上原票!$A:$P,12,0)*VLOOKUP("615-3",▼マッピング!$A:$G,5,0)/100,0)+IFERROR(VLOOKUP(C25,▼売上原票!$A:$P,13,0)*VLOOKUP("615-4",▼マッピング!$A:$G,5,0)/100,0) | H25: =D25+E25+F25+G25 | P25: =I25+J25+K25+L25+M25+N25+O25 | Q25: =H25-P25 | R25: =IF(H25<>0,Q25/H25,0) | S25: =IF(R25>=0.25,"◎ 優良",IF(R25>=0.15,"○ 良好",IF(R25>=0.05,"△ 要注意","× 赤字"))) | T25: =IF(H24<>0,H25/H24-1,"")
A26: C002 | B26: 都営地下鉄案件 | C26: 2024-10 | D26: =IFERROR(VLOOKUP(C26,▼売上原票!$A:$P,3,0)*VLOOKUP("612-1",▼マッピング!$A:$G,5,0)/100,0) | E26: =IFERROR(VLOOKUP(C26,▼売上原票!$A:$P,4,0)*VLOOKUP("612-2",▼マッピング!$A:$G,5,0)/100,0) | F26: =IFERROR(VLOOKUP(C26,▼売上原票!$A:$P,10,0)*VLOOKUP("615-1",▼マッピング!$A:$G,5,0)/100,0) | G26: =IFERROR(VLOOKUP(C26,▼売上原票!$A:$P,5,0)*VLOOKUP("613-1",▼マッピング!$A:$G,5,0)/100,0)+IFERROR(VLOOKUP(C26,▼売上原票!$A:$P,6,0)*VLOOKUP("613-2",▼マッピング!$A:$G,5,0)/100,0)+IFERROR(VLOOKUP(C26,▼売上原票!$A:$P,7,0)*VLOOKUP("614-1",▼マッピング!$A:$G,5,0)/100,0)+IFERROR(VLOOKUP(C26,▼売上原票!$A:$P,8,0)*VLOOKUP("614-2",▼マッピング!$A:$G,5,0)/100,0)+IFERROR(VLOOKUP(C26,▼売上原票!$A:$P,9,0)*VLOOKUP("614-3",▼マッピング!$A:$G,5,0)/100,0)+IFERROR(VLOOKUP(C26,▼売上原票!$A:$P,11,0)*VLOOKUP("615-2",▼マッピング!$A:$G,5,0)/100,0)+IFERROR(VLOOKUP(C26,▼売上原票!$A:$P,12,0)*VLOOKUP("615-3",▼マッピング!$A:$G,5,0)/100,0)+IFERROR(VLOOKUP(C26,▼売上原票!$A:$P,13,0)*VLOOKUP("615-4",▼マッピング!$A:$G,5,0)/100,0) | H26: =D26+E26+F26+G26 | P26: =I26+J26+K26+L26+M26+N26+O26 | Q26: =H26-P26 | R26: =IF(H26<>0,Q26/H26,0) | S26: =IF(R26>=0.25,"◎ 優良",IF(R26>=0.15,"○ 良好",IF(R26>=0.05,"△ 要注意","× 赤字"))) | T26: =IF(H25<>0,H26/H25-1,"")
A27: C002 | B27: 都営地下鉄案件 | C27: 2024-11 | D27: =IFERROR(VLOOKUP(C27,▼売上原票!$A:$P,3,0)*VLOOKUP("612-1",▼マッピング!$A:$G,5,0)/100,0) | E27: =IFERROR(VLOOKUP(C27,▼売上原票!$A:$P,4,0)*VLOOKUP("612-2",▼マッピング!$A:$G,5,0)/100,0) | F27: =IFERROR(VLOOKUP(C27,▼売上原票!$A:$P,10,0)*VLOOKUP("615-1",▼マッピング!$A:$G,5,0)/100,0) | G27: =IFERROR(VLOOKUP(C27,▼売上原票!$A:$P,5,0)*VLOOKUP("613-1",▼マッピング!$A:$G,5,0)/100,0)+IFERROR(VLOOKUP(C27,▼売上原票!$A:$P,6,0)*VLOOKUP("613-2",▼マッピング!$A:$G,5,0)/100,0)+IFERROR(VLOOKUP(C27,▼売上原票!$A:$P,7,0)*VLOOKUP("614-1",▼マッピング!$A:$G,5,0)/100,0)+IFERROR(VLOOKUP(C27,▼売上原票!$A:$P,8,0)*VLOOKUP("614-2",▼マッピング!$A:$G,5,0)/100,0)+IFERROR(VLOOKUP(C27,▼売上原票!$A:$P,9,0)*VLOOKUP("614-3",▼マッピング!$A:$G,5,0)/100,0)+IFERROR(VLOOKUP(C27,▼売上原票!$A:$P,11,0)*VLOOKUP("615-2",▼マッピング!$A:$G,5,0)/100,0)+IFERROR(VLOOKUP(C27,▼売上原票!$A:$P,12,0)*VLOOKUP("615-3",▼マッピング!$A:$G,5,0)/100,0)+IFERROR(VLOOKUP(C27,▼売上原票!$A:$P,13,0)*VLOOKUP("615-4",▼マッピング!$A:$G,5,0)/100,0) | H27: =D27+E27+F27+G27 | P27: =I27+J27+K27+L27+M27+N27+O27 | Q27: =H27-P27 | R27: =IF(H27<>0,Q27/H27,0) | S27: =IF(R27>=0.25,"◎ 優良",IF(R27>=0.15,"○ 良好",IF(R27>=0.05,"△ 要注意","× 赤字"))) | T27: =IF(H26<>0,H27/H26-1,"")
A28: C002 | B28: 都営地下鉄案件 | C28: 2024-12 | D28: =IFERROR(VLOOKUP(C28,▼売上原票!$A:$P,3,0)*VLOOKUP("612-1",▼マッピング!$A:$G,5,0)/100,0) | E28: =IFERROR(VLOOKUP(C28,▼売上原票!$A:$P,4,0)*VLOOKUP("612-2",▼マッピング!$A:$G,5,0)/100,0) | F28: =IFERROR(VLOOKUP(C28,▼売上原票!$A:$P,10,0)*VLOOKUP("615-1",▼マッピング!$A:$G,5,0)/100,0) | G28: =IFERROR(VLOOKUP(C28,▼売上原票!$A:$P,5,0)*VLOOKUP("613-1",▼マッピング!$A:$G,5,0)/100,0)+IFERROR(VLOOKUP(C28,▼売上原票!$A:$P,6,0)*VLOOKUP("613-2",▼マッピング!$A:$G,5,0)/100,0)+IFERROR(VLOOKUP(C28,▼売上原票!$A:$P,7,0)*VLOOKUP("614-1",▼マッピング!$A:$G,5,0)/100,0)+IFERROR(VLOOKUP(C28,▼売上原票!$A:$P,8,0)*VLOOKUP("614-2",▼マッピング!$A:$G,5,0)/100,0)+IFERROR(VLOOKUP(C28,▼売上原票!$A:$P,9,0)*VLOOKUP("614-3",▼マッピング!$A:$G,5,0)/100,0)+IFERROR(VLOOKUP(C28,▼売上原票!$A:$P,11,0)*VLOOKUP("615-2",▼マッピング!$A:$G,5,0)/100,0)+IFERROR(VLOOKUP(C28,▼売上原票!$A:$P,12,0)*VLOOKUP("615-3",▼マッピング!$A:$G,5,0)/100,0)+IFERROR(VLOOKUP(C28,▼売上原票!$A:$P,13,0)*VLOOKUP("615-4",▼マッピング!$A:$G,5,0)/100,0) | H28: =D28+E28+F28+G28 | P28: =I28+J28+K28+L28+M28+N28+O28 | Q28: =H28-P28 | R28: =IF(H28<>0,Q28/H28,0) | S28: =IF(R28>=0.25,"◎ 優良",IF(R28>=0.15,"○ 良好",IF(R28>=0.05,"△ 要注意","× 赤字"))) | T28: =IF(H27<>0,H28/H27-1,"")
A29: C002 | B29: 都営地下鉄案件 | C29: 2025-01 | D29: =IFERROR(VLOOKUP(C29,▼売上原票!$A:$P,3,0)*VLOOKUP("612-1",▼マッピング!$A:$G,5,0)/100,0) | E29: =IFERROR(VLOOKUP(C29,▼売上原票!$A:$P,4,0)*VLOOKUP("612-2",▼マッピング!$A:$G,5,0)/100,0) | F29: =IFERROR(VLOOKUP(C29,▼売上原票!$A:$P,10,0)*VLOOKUP("615-1",▼マッピング!$A:$G,5,0)/100,0) | G29: =IFERROR(VLOOKUP(C29,▼売上原票!$A:$P,5,0)*VLOOKUP("613-1",▼マッピング!$A:$G,5,0)/100,0)+IFERROR(VLOOKUP(C29,▼売上原票!$A:$P,6,0)*VLOOKUP("613-2",▼マッピング!$A:$G,5,0)/100,0)+IFERROR(VLOOKUP(C29,▼売上原票!$A:$P,7,0)*VLOOKUP("614-1",▼マッピング!$A:$G,5,0)/100,0)+IFERROR(VLOOKUP(C29,▼売上原票!$A:$P,8,0)*VLOOKUP("614-2",▼マッピング!$A:$G,5,0)/100,0)+IFERROR(VLOOKUP(C29,▼売上原票!$A:$P,9,0)*VLOOKUP("614-3",▼マッピング!$A:$G,5,0)/100,0)+IFERROR(VLOOKUP(C29,▼売上原票!$A:$P,11,0)*VLOOKUP("615-2",▼マッピング!$A:$G,5,0)/100,0)+IFERROR(VLOOKUP(C29,▼売上原票!$A:$P,12,0)*VLOOKUP("615-3",▼マッピング!$A:$G,5,0)/100,0)+IFERROR(VLOOKUP(C29,▼売上原票!$A:$P,13,0)*VLOOKUP("615-4",▼マッピング!$A:$G,5,0)/100,0) | H29: =D29+E29+F29+G29 | P29: =I29+J29+K29+L29+M29+N29+O29 | Q29: =H29-P29 | R29: =IF(H29<>0,Q29/H29,0) | S29: =IF(R29>=0.25,"◎ 優良",IF(R29>=0.15,"○ 良好",IF(R29>=0.05,"△ 要注意","× 赤字"))) | T29: =IF(H28<>0,H29/H28-1,"")
A30: C002 | B30: 都営地下鉄案件 | C30: 2025-02 | D30: =IFERROR(VLOOKUP(C30,▼売上原票!$A:$P,3,0)*VLOOKUP("612-1",▼マッピング!$A:$G,5,0)/100,0) | E30: =IFERROR(VLOOKUP(C30,▼売上原票!$A:$P,4,0)*VLOOKUP("612-2",▼マッピング!$A:$G,5,0)/100,0) | F30: =IFERROR(VLOOKUP(C30,▼売上原票!$A:$P,10,0)*VLOOKUP("615-1",▼マッピング!$A:$G,5,0)/100,0) | G30: =IFERROR(VLOOKUP(C30,▼売上原票!$A:$P,5,0)*VLOOKUP("613-1",▼マッピング!$A:$G,5,0)/100,0)+IFERROR(VLOOKUP(C30,▼売上原票!$A:$P,6,0)*VLOOKUP("613-2",▼マッピング!$A:$G,5,0)/100,0)+IFERROR(VLOOKUP(C30,▼売上原票!$A:$P,7,0)*VLOOKUP("614-1",▼マッピング!$A:$G,5,0)/100,0)+IFERROR(VLOOKUP(C30,▼売上原票!$A:$P,8,0)*VLOOKUP("614-2",▼マッピング!$A:$G,5,0)/100,0)+IFERROR(VLOOKUP(C30,▼売上原票!$A:$P,9,0)*VLOOKUP("614-3",▼マッピング!$A:$G,5,0)/100,0)+IFERROR(VLOOKUP(C30,▼売上原票!$A:$P,11,0)*VLOOKUP("615-2",▼マッピング!$A:$G,5,0)/100,0)+IFERROR(VLOOKUP(C30,▼売上原票!$A:$P,12,0)*VLOOKUP("615-3",▼マッピング!$A:$G,5,0)/100,0)+IFERROR(VLOOKUP(C30,▼売上原票!$A:$P,13,0)*VLOOKUP("615-4",▼マッピング!$A:$G,5,0)/100,0) | H30: =D30+E30+F30+G30 | P30: =I30+J30+K30+L30+M30+N30+O30 | Q30: =H30-P30 | R30: =IF(H30<>0,Q30/H30,0) | S30: =IF(R30>=0.25,"◎ 優良",IF(R30>=0.15,"○ 良好",IF(R30>=0.05,"△ 要注意","× 赤字"))) | T30: =IF(H29<>0,H30/H29-1,"")
A31: C002 | B31: 都営地下鉄案件 | C31: 2025-03 | D31: =IFERROR(VLOOKUP(C31,▼売上原票!$A:$P,3,0)*VLOOKUP("612-1",▼マッピング!$A:$G,5,0)/100,0) | E31: =IFERROR(VLOOKUP(C31,▼売上原票!$A:$P,4,0)*VLOOKUP("612-2",▼マッピング!$A:$G,5,0)/100,0) | F31: =IFERROR(VLOOKUP(C31,▼売上原票!$A:$P,10,0)*VLOOKUP("615-1",▼マッピング!$A:$G,5,0)/100,0) | G31: =IFERROR(VLOOKUP(C31,▼売上原票!$A:$P,5,0)*VLOOKUP("613-1",▼マッピング!$A:$G,5,0)/100,0)+IFERROR(VLOOKUP(C31,▼売上原票!$A:$P,6,0)*VLOOKUP("613-2",▼マッピング!$A:$G,5,0)/100,0)+IFERROR(VLOOKUP(C31,▼売上原票!$A:$P,7,0)*VLOOKUP("614-1",▼マッピング!$A:$G,5,0)/100,0)+IFERROR(VLOOKUP(C31,▼売上原票!$A:$P,8,0)*VLOOKUP("614-2",▼マッピング!$A:$G,5,0)/100,0)+IFERROR(VLOOKUP(C31,▼売上原票!$A:$P,9,0)*VLOOKUP("614-3",▼マッピング!$A:$G,5,0)/100,0)+IFERROR(VLOOKUP(C31,▼売上原票!$A:$P,11,0)*VLOOKUP("615-2",▼マッピング!$A:$G,5,0)/100,0)+IFERROR(VLOOKUP(C31,▼売上原票!$A:$P,12,0)*VLOOKUP("615-3",▼マッピング!$A:$G,5,0)/100,0)+IFERROR(VLOOKUP(C31,▼売上原票!$A:$P,13,0)*VLOOKUP("615-4",▼マッピング!$A:$G,5,0)/100,0) | H31: =D31+E31+F31+G31 | P31: =I31+J31+K31+L31+M31+N31+O31 | Q31: =H31-P31 | R31: =IF(H31<>0,Q31/H31,0) | S31: =IF(R31>=0.25,"◎ 優良",IF(R31>=0.15,"○ 良好",IF(R31>=0.05,"△ 要注意","× 赤字"))) | T31: =IF(H30<>0,H31/H30-1,"")
A32: C002 | B32: 都営地下鉄案件 | C32: 2025-04 | D32: =IFERROR(VLOOKUP(C32,▼売上原票!$A:$P,3,0)*VLOOKUP("612-1",▼マッピング!$A:$G,5,0)/100,0) | E32: =IFERROR(VLOOKUP(C32,▼売上原票!$A:$P,4,0)*VLOOKUP("612-2",▼マッピング!$A:$G,5,0)/100,0) | F32: =IFERROR(VLOOKUP(C32,▼売上原票!$A:$P,10,0)*VLOOKUP("615-1",▼マッピング!$A:$G,5,0)/100,0) | G32: =IFERROR(VLOOKUP(C32,▼売上原票!$A:$P,5,0)*VLOOKUP("613-1",▼マッピング!$A:$G,5,0)/100,0)+IFERROR(VLOOKUP(C32,▼売上原票!$A:$P,6,0)*VLOOKUP("613-2",▼マッピング!$A:$G,5,0)/100,0)+IFERROR(VLOOKUP(C32,▼売上原票!$A:$P,7,0)*VLOOKUP("614-1",▼マッピング!$A:$G,5,0)/100,0)+IFERROR(VLOOKUP(C32,▼売上原票!$A:$P,8,0)*VLOOKUP("614-2",▼マッピング!$A:$G,5,0)/100,0)+IFERROR(VLOOKUP(C32,▼売上原票!$A:$P,9,0)*VLOOKUP("614-3",▼マッピング!$A:$G,5,0)/100,0)+IFERROR(VLOOKUP(C32,▼売上原票!$A:$P,11,0)*VLOOKUP("615-2",▼マッピング!$A:$G,5,0)/100,0)+IFERROR(VLOOKUP(C32,▼売上原票!$A:$P,12,0)*VLOOKUP("615-3",▼マッピング!$A:$G,5,0)/100,0)+IFERROR(VLOOKUP(C32,▼売上原票!$A:$P,13,0)*VLOOKUP("615-4",▼マッピング!$A:$G,5,0)/100,0) | H32: =D32+E32+F32+G32 | P32: =I32+J32+K32+L32+M32+N32+O32 | Q32: =H32-P32 | R32: =IF(H32<>0,Q32/H32,0) | S32: =IF(R32>=0.25,"◎ 優良",IF(R32>=0.15,"○ 良好",IF(R32>=0.05,"△ 要注意","× 赤字"))) | T32: =IF(H31<>0,H32/H31-1,"")
A33: C002 | B33: 都営地下鉄案件 | C33: 2025-05 | D33: =IFERROR(VLOOKUP(C33,▼売上原票!$A:$P,3,0)*VLOOKUP("612-1",▼マッピング!$A:$G,5,0)/100,0) | E33: =IFERROR(VLOOKUP(C33,▼売上原票!$A:$P,4,0)*VLOOKUP("612-2",▼マッピング!$A:$G,5,0)/100,0) | F33: =IFERROR(VLOOKUP(C33,▼売上原票!$A:$P,10,0)*VLOOKUP("615-1",▼マッピング!$A:$G,5,0)/100,0) | G33: =IFERROR(VLOOKUP(C33,▼売上原票!$A:$P,5,0)*VLOOKUP("613-1",▼マッピング!$A:$G,5,0)/100,0)+IFERROR(VLOOKUP(C33,▼売上原票!$A:$P,6,0)*VLOOKUP("613-2",▼マッピング!$A:$G,5,0)/100,0)+IFERROR(VLOOKUP(C33,▼売上原票!$A:$P,7,0)*VLOOKUP("614-1",▼マッピング!$A:$G,5,0)/100,0)+IFERROR(VLOOKUP(C33,▼売上原票!$A:$P,8,0)*VLOOKUP("614-2",▼マッピング!$A:$G,5,0)/100,0)+IFERROR(VLOOKUP(C33,▼売上原票!$A:$P,9,0)*VLOOKUP("614-3",▼マッピング!$A:$G,5,0)/100,0)+IFERROR(VLOOKUP(C33,▼売上原票!$A:$P,11,0)*VLOOKUP("615-2",▼マッピング!$A:$G,5,0)/100,0)+IFERROR(VLOOKUP(C33,▼売上原票!$A:$P,12,0)*VLOOKUP("615-3",▼マッピング!$A:$G,5,0)/100,0)+IFERROR(VLOOKUP(C33,▼売上原票!$A:$P,13,0)*VLOOKUP("615-4",▼マッピング!$A:$G,5,0)/100,0) | H33: =D33+E33+F33+G33 | P33: =I33+J33+K33+L33+M33+N33+O33 | Q33: =H33-P33 | R33: =IF(H33<>0,Q33/H33,0) | S33: =IF(R33>=0.25,"◎ 優良",IF(R33>=0.15,"○ 良好",IF(R33>=0.05,"△ 要注意","× 赤字"))) | T33: =IF(H32<>0,H33/H32-1,"")
A34: C002 | B34: 都営地下鉄案件 | C34: 2025-06 | D34: =IFERROR(VLOOKUP(C34,▼売上原票!$A:$P,3,0)*VLOOKUP("612-1",▼マッピング!$A:$G,5,0)/100,0) | E34: =IFERROR(VLOOKUP(C34,▼売上原票!$A:$P,4,0)*VLOOKUP("612-2",▼マッピング!$A:$G,5,0)/100,0) | F34: =IFERROR(VLOOKUP(C34,▼売上原票!$A:$P,10,0)*VLOOKUP("615-1",▼マッピング!$A:$G,5,0)/100,0) | G34: =IFERROR(VLOOKUP(C34,▼売上原票!$A:$P,5,0)*VLOOKUP("613-1",▼マッピング!$A:$G,5,0)/100,0)+IFERROR(VLOOKUP(C34,▼売上原票!$A:$P,6,0)*VLOOKUP("613-2",▼マッピング!$A:$G,5,0)/100,0)+IFERROR(VLOOKUP(C34,▼売上原票!$A:$P,7,0)*VLOOKUP("614-1",▼マッピング!$A:$G,5,0)/100,0)+IFERROR(VLOOKUP(C34,▼売上原票!$A:$P,8,0)*VLOOKUP("614-2",▼マッピング!$A:$G,5,0)/100,0)+IFERROR(VLOOKUP(C34,▼売上原票!$A:$P,9,0)*VLOOKUP("614-3",▼マッピング!$A:$G,5,0)/100,0)+IFERROR(VLOOKUP(C34,▼売上原票!$A:$P,11,0)*VLOOKUP("615-2",▼マッピング!$A:$G,5,0)/100,0)+IFERROR(VLOOKUP(C34,▼売上原票!$A:$P,12,0)*VLOOKUP("615-3",▼マッピング!$A:$G,5,0)/100,0)+IFERROR(VLOOKUP(C34,▼売上原票!$A:$P,13,0)*VLOOKUP("615-4",▼マッピング!$A:$G,5,0)/100,0) | H34: =D34+E34+F34+G34 | P34: =I34+J34+K34+L34+M34+N34+O34 | Q34: =H34-P34 | R34: =IF(H34<>0,Q34/H34,0) | S34: =IF(R34>=0.25,"◎ 優良",IF(R34>=0.15,"○ 良好",IF(R34>=0.05,"△ 要注意","× 赤字"))) | T34: =IF(H33<>0,H34/H33-1,"")
A35: C002 | B35: 都営地下鉄案件 | C35: 2025-07 | D35: =IFERROR(VLOOKUP(C35,▼売上原票!$A:$P,3,0)*VLOOKUP("612-1",▼マッピング!$A:$G,5,0)/100,0) | E35: =IFERROR(VLOOKUP(C35,▼売上原票!$A:$P,4,0)*VLOOKUP("612-2",▼マッピング!$A:$G,5,0)/100,0) | F35: =IFERROR(VLOOKUP(C35,▼売上原票!$A:$P,10,0)*VLOOKUP("615-1",▼マッピング!$A:$G,5,0)/100,0) | G35: =IFERROR(VLOOKUP(C35,▼売上原票!$A:$P,5,0)*VLOOKUP("613-1",▼マッピング!$A:$G,5,0)/100,0)+IFERROR(VLOOKUP(C35,▼売上原票!$A:$P,6,0)*VLOOKUP("613-2",▼マッピング!$A:$G,5,0)/100,0)+IFERROR(VLOOKUP(C35,▼売上原票!$A:$P,7,0)*VLOOKUP("614-1",▼マッピング!$A:$G,5,0)/100,0)+IFERROR(VLOOKUP(C35,▼売上原票!$A:$P,8,0)*VLOOKUP("614-2",▼マッピング!$A:$G,5,0)/100,0)+IFERROR(VLOOKUP(C35,▼売上原票!$A:$P,9,0)*VLOOKUP("614-3",▼マッピング!$A:$G,5,0)/100,0)+IFERROR(VLOOKUP(C35,▼売上原票!$A:$P,11,0)*VLOOKUP("615-2",▼マッピング!$A:$G,5,0)/100,0)+IFERROR(VLOOKUP(C35,▼売上原票!$A:$P,12,0)*VLOOKUP("615-3",▼マッピング!$A:$G,5,0)/100,0)+IFERROR(VLOOKUP(C35,▼売上原票!$A:$P,13,0)*VLOOKUP("615-4",▼マッピング!$A:$G,5,0)/100,0) | H35: =D35+E35+F35+G35 | P35: =I35+J35+K35+L35+M35+N35+O35 | Q35: =H35-P35 | R35: =IF(H35<>0,Q35/H35,0) | S35: =IF(R35>=0.25,"◎ 優良",IF(R35>=0.15,"○ 良好",IF(R35>=0.05,"△ 要注意","× 赤字"))) | T35: =IF(H34<>0,H35/H34-1,"")
... A39: C002 | B39: 都営地下鉄案件 | C39: 2025-11 | D39: =IFERROR(VLOOKUP(C39,▼売上原票!$A:$P,3,0)*VLOOKUP("612-1",▼マッピング!$A:$G,5,0)/100,0) | E39: =IFERROR(VLOOKUP(C39,▼売上原票!$A:$P,4,0)*VLOOKUP("612-2",▼マッピング!$A:$G,5,0)/100,0) | F39: =IFERROR(VLOOKUP(C39,▼売上原票!$A:$P,10,0)*VLOOKUP("615-1",▼マッピング!$A:$G,5,0)/100,0) | G39: =IFERROR(VLOOKUP(C39,▼売上原票!$A:$P,5,0)*VLOOKUP("613-1",▼マッピング!$A:$G,5,0)/100,0)+IFERROR(VLOOKUP(C39,▼売上原票!$A:$P,6,0)*VLOOKUP("613-2",▼マッピング!$A:$G,5,0)/100,0)+IFERROR(VLOOKUP(C39,▼売上原票!$A:$P,7,0)*VLOOKUP("614-1",▼マッピング!$A:$G,5,0)/100,0)+IFERROR(VLOOKUP(C39,▼売上原票!$A:$P,8,0)*VLOOKUP("614-2",▼マッピング!$A:$G,5,0)/100,0)+IFERROR(VLOOKUP(C39,▼売上原票!$A:$P,9,0)*VLOOKUP("614-3",▼マッピング!$A:$G,5,0)/100,0)+IFERROR(VLOOKUP(C39,▼売上原票!$A:$P,11,0)*VLOOKUP("615-2",▼マッピング!$A:$G,5,0)/100,0)+IFERROR(VLOOKUP(C39,▼売上原票!$A:$P,12,0)*VLOOKUP("615-3",▼マッピング!$A:$G,5,0)/100,0)+IFERROR(VLOOKUP(C39,▼売上原票!$A:$P,13,0)*VLOOKUP("615-4",▼マッピング!$A:$G,5,0)/100,0) | H39: =D39+E39+F39+G39 | P39: =I39+J39+K39+L39+M39+N39+O39 | Q39: =H39-P39 | R39: =IF(H39<>0,Q39/H39,0) | S39: =IF(R39>=0.25,"◎ 優良",IF(R39>=0.15,"○ 良好",IF(R39>=0.05,"△ 要注意","× 赤字"))) | T39: =IF(H38<>0,H39/H38-1,"")
A41: C003 | B41: 一般事業者案件 | C41: 2024-07 | D41: =IFERROR(VLOOKUP(C41,▼売上原票!$A:$P,3,0)*VLOOKUP("612-1",▼マッピング!$A:$G,6,0)/100,0) | E41: =IFERROR(VLOOKUP(C41,▼売上原票!$A:$P,4,0)*VLOOKUP("612-2",▼マッピング!$A:$G,6,0)/100,0) | F41: =IFERROR(VLOOKUP(C41,▼売上原票!$A:$P,10,0)*VLOOKUP("615-1",▼マッピング!$A:$G,6,0)/100,0) | G41: =IFERROR(VLOOKUP(C41,▼売上原票!$A:$P,5,0)*VLOOKUP("613-1",▼マッピング!$A:$G,6,0)/100,0)+IFERROR(VLOOKUP(C41,▼売上原票!$A:$P,6,0)*VLOOKUP("613-2",▼マッピング!$A:$G,6,0)/100,0)+IFERROR(VLOOKUP(C41,▼売上原票!$A:$P,7,0)*VLOOKUP("614-1",▼マッピング!$A:$G,6,0)/100,0)+IFERROR(VLOOKUP(C41,▼売上原票!$A:$P,8,0)*VLOOKUP("614-2",▼マッピング!$A:$G,6,0)/100,0)+IFERROR(VLOOKUP(C41,▼売上原票!$A:$P,9,0)*VLOOKUP("614-3",▼マッピング!$A:$G,6,0)/100,0)+IFERROR(VLOOKUP(C41,▼売上原票!$A:$P,11,0)*VLOOKUP("615-2",▼マッピング!$A:$G,6,0)/100,0)+IFERROR(VLOOKUP(C41,▼売上原票!$A:$P,12,0)*VLOOKUP("615-3",▼マッピング!$A:$G,6,0)/100,0)+IFERROR(VLOOKUP(C41,▼売上原票!$A:$P,13,0)*VLOOKUP("615-4",▼マッピング!$A:$G,6,0)/100,0) | H41: =D41+E41+F41+G41 | P41: =I41+J41+K41+L41+M41+N41+O41 | Q41: =H41-P41 | R41: =IF(H41<>0,Q41/H41,0) | S41: =IF(R41>=0.25,"◎ 優良",IF(R41>=0.15,"○ 良好",IF(R41>=0.05,"△ 要注意","× 赤字"))) | T41: —
A42: C003 | B42: 一般事業者案件 | C42: 2024-08 | D42: =IFERROR(VLOOKUP(C42,▼売上原票!$A:$P,3,0)*VLOOKUP("612-1",▼マッピング!$A:$G,6,0)/100,0) | E42: =IFERROR(VLOOKUP(C42,▼売上原票!$A:$P,4,0)*VLOOKUP("612-2",▼マッピング!$A:$G,6,0)/100,0) | F42: =IFERROR(VLOOKUP(C42,▼売上原票!$A:$P,10,0)*VLOOKUP("615-1",▼マッピング!$A:$G,6,0)/100,0) | G42: =IFERROR(VLOOKUP(C42,▼売上原票!$A:$P,5,0)*VLOOKUP("613-1",▼マッピング!$A:$G,6,0)/100,0)+IFERROR(VLOOKUP(C42,▼売上原票!$A:$P,6,0)*VLOOKUP("613-2",▼マッピング!$A:$G,6,0)/100,0)+IFERROR(VLOOKUP(C42,▼売上原票!$A:$P,7,0)*VLOOKUP("614-1",▼マッピング!$A:$G,6,0)/100,0)+IFERROR(VLOOKUP(C42,▼売上原票!$A:$P,8,0)*VLOOKUP("614-2",▼マッピング!$A:$G,6,0)/100,0)+IFERROR(VLOOKUP(C42,▼売上原票!$A:$P,9,0)*VLOOKUP("614-3",▼マッピング!$A:$G,6,0)/100,0)+IFERROR(VLOOKUP(C42,▼売上原票!$A:$P,11,0)*VLOOKUP("615-2",▼マッピング!$A:$G,6,0)/100,0)+IFERROR(VLOOKUP(C42,▼売上原票!$A:$P,12,0)*VLOOKUP("615-3",▼マッピング!$A:$G,6,0)/100,0)+IFERROR(VLOOKUP(C42,▼売上原票!$A:$P,13,0)*VLOOKUP("615-4",▼マッピング!$A:$G,6,0)/100,0) | H42: =D42+E42+F42+G42 | P42: =I42+J42+K42+L42+M42+N42+O42 | Q42: =H42-P42 | R42: =IF(H42<>0,Q42/H42,0) | S42: =IF(R42>=0.25,"◎ 優良",IF(R42>=0.15,"○ 良好",IF(R42>=0.05,"△ 要注意","× 赤字"))) | T42: =IF(H41<>0,H42/H41-1,"")
A43: C003 | B43: 一般事業者案件 | C43: 2024-09 | D43: =IFERROR(VLOOKUP(C43,▼売上原票!$A:$P,3,0)*VLOOKUP("612-1",▼マッピング!$A:$G,6,0)/100,0) | E43: =IFERROR(VLOOKUP(C43,▼売上原票!$A:$P,4,0)*VLOOKUP("612-2",▼マッピング!$A:$G,6,0)/100,0) | F43: =IFERROR(VLOOKUP(C43,▼売上原票!$A:$P,10,0)*VLOOKUP("615-1",▼マッピング!$A:$G,6,0)/100,0) | G43: =IFERROR(VLOOKUP(C43,▼売上原票!$A:$P,5,0)*VLOOKUP("613-1",▼マッピング!$A:$G,6,0)/100,0)+IFERROR(VLOOKUP(C43,▼売上原票!$A:$P,6,0)*VLOOKUP("613-2",▼マッピング!$A:$G,6,0)/100,0)+IFERROR(VLOOKUP(C43,▼売上原票!$A:$P,7,0)*VLOOKUP("614-1",▼マッピング!$A:$G,6,0)/100,0)+IFERROR(VLOOKUP(C43,▼売上原票!$A:$P,8,0)*VLOOKUP("614-2",▼マッピング!$A:$G,6,0)/100,0)+IFERROR(VLOOKUP(C43,▼売上原票!$A:$P,9,0)*VLOOKUP("614-3",▼マッピング!$A:$G,6,0)/100,0)+IFERROR(VLOOKUP(C43,▼売上原票!$A:$P,11,0)*VLOOKUP("615-2",▼マッピング!$A:$G,6,0)/100,0)+IFERROR(VLOOKUP(C43,▼売上原票!$A:$P,12,0)*VLOOKUP("615-3",▼マッピング!$A:$G,6,0)/100,0)+IFERROR(VLOOKUP(C43,▼売上原票!$A:$P,13,0)*VLOOKUP("615-4",▼マッピング!$A:$G,6,0)/100,0) | H43: =D43+E43+F43+G43 | P43: =I43+J43+K43+L43+M43+N43+O43 | Q43: =H43-P43 | R43: =IF(H43<>0,Q43/H43,0) | S43: =IF(R43>=0.25,"◎ 優良",IF(R43>=0.15,"○ 良好",IF(R43>=0.05,"△ 要注意","× 赤字"))) | T43: =IF(H42<>0,H43/H42-1,"")
A44: C003 | B44: 一般事業者案件 | C44: 2024-10 | D44: =IFERROR(VLOOKUP(C44,▼売上原票!$A:$P,3,0)*VLOOKUP("612-1",▼マッピング!$A:$G,6,0)/100,0) | E44: =IFERROR(VLOOKUP(C44,▼売上原票!$A:$P,4,0)*VLOOKUP("612-2",▼マッピング!$A:$G,6,0)/100,0) | F44: =IFERROR(VLOOKUP(C44,▼売上原票!$A:$P,10,0)*VLOOKUP("615-1",▼マッピング!$A:$G,6,0)/100,0) | G44: =IFERROR(VLOOKUP(C44,▼売上原票!$A:$P,5,0)*VLOOKUP("613-1",▼マッピング!$A:$G,6,0)/100,0)+IFERROR(VLOOKUP(C44,▼売上原票!$A:$P,6,0)*VLOOKUP("613-2",▼マッピング!$A:$G,6,0)/100,0)+IFERROR(VLOOKUP(C44,▼売上原票!$A:$P,7,0)*VLOOKUP("614-1",▼マッピング!$A:$G,6,0)/100,0)+IFERROR(VLOOKUP(C44,▼売上原票!$A:$P,8,0)*VLOOKUP("614-2",▼マッピング!$A:$G,6,0)/100,0)+IFERROR(VLOOKUP(C44,▼売上原票!$A:$P,9,0)*VLOOKUP("614-3",▼マッピング!$A:$G,6,0)/100,0)+IFERROR(VLOOKUP(C44,▼売上原票!$A:$P,11,0)*VLOOKUP("615-2",▼マッピング!$A:$G,6,0)/100,0)+IFERROR(VLOOKUP(C44,▼売上原票!$A:$P,12,0)*VLOOKUP("615-3",▼マッピング!$A:$G,6,0)/100,0)+IFERROR(VLOOKUP(C44,▼売上原票!$A:$P,13,0)*VLOOKUP("615-4",▼マッピング!$A:$G,6,0)/100,0) | H44: =D44+E44+F44+G44 | P44: =I44+J44+K44+L44+M44+N44+O44 | Q44: =H44-P44 | R44: =IF(H44<>0,Q44/H44,0) | S44: =IF(R44>=0.25,"◎ 優良",IF(R44>=0.15,"○ 良好",IF(R44>=0.05,"△ 要注意","× 赤字"))) | T44: =IF(H43<>0,H44/H43-1,"")
A45: C003 | B45: 一般事業者案件 | C45: 2024-11 | D45: =IFERROR(VLOOKUP(C45,▼売上原票!$A:$P,3,0)*VLOOKUP("612-1",▼マッピング!$A:$G,6,0)/100,0) | E45: =IFERROR(VLOOKUP(C45,▼売上原票!$A:$P,4,0)*VLOOKUP("612-2",▼マッピング!$A:$G,6,0)/100,0) | F45: =IFERROR(VLOOKUP(C45,▼売上原票!$A:$P,10,0)*VLOOKUP("615-1",▼マッピング!$A:$G,6,0)/100,0) | G45: =IFERROR(VLOOKUP(C45,▼売上原票!$A:$P,5,0)*VLOOKUP("613-1",▼マッピング!$A:$G,6,0)/100,0)+IFERROR(VLOOKUP(C45,▼売上原票!$A:$P,6,0)*VLOOKUP("613-2",▼マッピング!$A:$G,6,0)/100,0)+IFERROR(VLOOKUP(C45,▼売上原票!$A:$P,7,0)*VLOOKUP("614-1",▼マッピング!$A:$G,6,0)/100,0)+IFERROR(VLOOKUP(C45,▼売上原票!$A:$P,8,0)*VLOOKUP("614-2",▼マッピング!$A:$G,6,0)/100,0)+IFERROR(VLOOKUP(C45,▼売上原票!$A:$P,9,0)*VLOOKUP("614-3",▼マッピング!$A:$G,6,0)/100,0)+IFERROR(VLOOKUP(C45,▼売上原票!$A:$P,11,0)*VLOOKUP("615-2",▼マッピング!$A:$G,6,0)/100,0)+IFERROR(VLOOKUP(C45,▼売上原票!$A:$P,12,0)*VLOOKUP("615-3",▼マッピング!$A:$G,6,0)/100,0)+IFERROR(VLOOKUP(C45,▼売上原票!$A:$P,13,0)*VLOOKUP("615-4",▼マッピング!$A:$G,6,0)/100,0) | H45: =D45+E45+F45+G45 | P45: =I45+J45+K45+L45+M45+N45+O45 | Q45: =H45-P45 | R45: =IF(H45<>0,Q45/H45,0) | S45: =IF(R45>=0.25,"◎ 優良",IF(R45>=0.15,"○ 良好",IF(R45>=0.05,"△ 要注意","× 赤字"))) | T45: =IF(H44<>0,H45/H44-1,"")
A46: C003 | B46: 一般事業者案件 | C46: 2024-12 | D46: =IFERROR(VLOOKUP(C46,▼売上原票!$A:$P,3,0)*VLOOKUP("612-1",▼マッピング!$A:$G,6,0)/100,0) | E46: =IFERROR(VLOOKUP(C46,▼売上原票!$A:$P,4,0)*VLOOKUP("612-2",▼マッピング!$A:$G,6,0)/100,0) | F46: =IFERROR(VLOOKUP(C46,▼売上原票!$A:$P,10,0)*VLOOKUP("615-1",▼マッピング!$A:$G,6,0)/100,0) | G46: =IFERROR(VLOOKUP(C46,▼売上原票!$A:$P,5,0)*VLOOKUP("613-1",▼マッピング!$A:$G,6,0)/100,0)+IFERROR(VLOOKUP(C46,▼売上原票!$A:$P,6,0)*VLOOKUP("613-2",▼マッピング!$A:$G,6,0)/100,0)+IFERROR(VLOOKUP(C46,▼売上原票!$A:$P,7,0)*VLOOKUP("614-1",▼マッピング!$A:$G,6,0)/100,0)+IFERROR(VLOOKUP(C46,▼売上原票!$A:$P,8,0)*VLOOKUP("614-2",▼マッピング!$A:$G,6,0)/100,0)+IFERROR(VLOOKUP(C46,▼売上原票!$A:$P,9,0)*VLOOKUP("614-3",▼マッピング!$A:$G,6,0)/100,0)+IFERROR(VLOOKUP(C46,▼売上原票!$A:$P,11,0)*VLOOKUP("615-2",▼マッピング!$A:$G,6,0)/100,0)+IFERROR(VLOOKUP(C46,▼売上原票!$A:$P,12,0)*VLOOKUP("615-3",▼マッピング!$A:$G,6,0)/100,0)+IFERROR(VLOOKUP(C46,▼売上原票!$A:$P,13,0)*VLOOKUP("615-4",▼マッピング!$A:$G,6,0)/100,0) | H46: =D46+E46+F46+G46 | P46: =I46+J46+K46+L46+M46+N46+O46 | Q46: =H46-P46 | R46: =IF(H46<>0,Q46/H46,0) | S46: =IF(R46>=0.25,"◎ 優良",IF(R46>=0.15,"○ 良好",IF(R46>=0.05,"△ 要注意","× 赤字"))) | T46: =IF(H45<>0,H46/H45-1,"")
A47: C003 | B47: 一般事業者案件 | C47: 2025-01 | D47: =IFERROR(VLOOKUP(C47,▼売上原票!$A:$P,3,0)*VLOOKUP("612-1",▼マッピング!$A:$G,6,0)/100,0) | E47: =IFERROR(VLOOKUP(C47,▼売上原票!$A:$P,4,0)*VLOOKUP("612-2",▼マッピング!$A:$G,6,0)/100,0) | F47: =IFERROR(VLOOKUP(C47,▼売上原票!$A:$P,10,0)*VLOOKUP("615-1",▼マッピング!$A:$G,6,0)/100,0) | G47: =IFERROR(VLOOKUP(C47,▼売上原票!$A:$P,5,0)*VLOOKUP("613-1",▼マッピング!$A:$G,6,0)/100,0)+IFERROR(VLOOKUP(C47,▼売上原票!$A:$P,6,0)*VLOOKUP("613-2",▼マッピング!$A:$G,6,0)/100,0)+IFERROR(VLOOKUP(C47,▼売上原票!$A:$P,7,0)*VLOOKUP("614-1",▼マッピング!$A:$G,6,0)/100,0)+IFERROR(VLOOKUP(C47,▼売上原票!$A:$P,8,0)*VLOOKUP("614-2",▼マッピング!$A:$G,6,0)/100,0)+IFERROR(VLOOKUP(C47,▼売上原票!$A:$P,9,0)*VLOOKUP("614-3",▼マッピング!$A:$G,6,0)/100,0)+IFERROR(VLOOKUP(C47,▼売上原票!$A:$P,11,0)*VLOOKUP("615-2",▼マッピング!$A:$G,6,0)/100,0)+IFERROR(VLOOKUP(C47,▼売上原票!$A:$P,12,0)*VLOOKUP("615-3",▼マッピング!$A:$G,6,0)/100,0)+IFERROR(VLOOKUP(C47,▼売上原票!$A:$P,13,0)*VLOOKUP("615-4",▼マッピング!$A:$G,6,0)/100,0) | H47: =D47+E47+F47+G47 | P47: =I47+J47+K47+L47+M47+N47+O47 | Q47: =H47-P47 | R47: =IF(H47<>0,Q47/H47,0) | S47: =IF(R47>=0.25,"◎ 優良",IF(R47>=0.15,"○ 良好",IF(R47>=0.05,"△ 要注意","× 赤字"))) | T47: =IF(H46<>0,H47/H46-1,"")
A48: C003 | B48: 一般事業者案件 | C48: 2025-02 | D48: =IFERROR(VLOOKUP(C48,▼売上原票!$A:$P,3,0)*VLOOKUP("612-1",▼マッピング!$A:$G,6,0)/100,0) | E48: =IFERROR(VLOOKUP(C48,▼売上原票!$A:$P,4,0)*VLOOKUP("612-2",▼マッピング!$A:$G,6,0)/100,0) | F48: =IFERROR(VLOOKUP(C48,▼売上原票!$A:$P,10,0)*VLOOKUP("615-1",▼マッピング!$A:$G,6,0)/100,0) | G48: =IFERROR(VLOOKUP(C48,▼売上原票!$A:$P,5,0)*VLOOKUP("613-1",▼マッピング!$A:$G,6,0)/100,0)+IFERROR(VLOOKUP(C48,▼売上原票!$A:$P,6,0)*VLOOKUP("613-2",▼マッピング!$A:$G,6,0)/100,0)+IFERROR(VLOOKUP(C48,▼売上原票!$A:$P,7,0)*VLOOKUP("614-1",▼マッピング!$A:$G,6,0)/100,0)+IFERROR(VLOOKUP(C48,▼売上原票!$A:$P,8,0)*VLOOKUP("614-2",▼マッピング!$A:$G,6,0)/100,0)+IFERROR(VLOOKUP(C48,▼売上原票!$A:$P,9,0)*VLOOKUP("614-3",▼マッピング!$A:$G,6,0)/100,0)+IFERROR(VLOOKUP(C48,▼売上原票!$A:$P,11,0)*VLOOKUP("615-2",▼マッピング!$A:$G,6,0)/100,0)+IFERROR(VLOOKUP(C48,▼売上原票!$A:$P,12,0)*VLOOKUP("615-3",▼マッピング!$A:$G,6,0)/100,0)+IFERROR(VLOOKUP(C48,▼売上原票!$A:$P,13,0)*VLOOKUP("615-4",▼マッピング!$A:$G,6,0)/100,0) | H48: =D48+E48+F48+G48 | P48: =I48+J48+K48+L48+M48+N48+O48 | Q48: =H48-P48 | R48: =IF(H48<>0,Q48/H48,0) | S48: =IF(R48>=0.25,"◎ 優良",IF(R48>=0.15,"○ 良好",IF(R48>=0.05,"△ 要注意","× 赤字"))) | T48: =IF(H47<>0,H48/H47-1,"")
...

Sheet ルート別採算
A1: ルート別 採算管理 （ルート = 科目コード / 各営業担当）
A2: 【売上】⑤売上原票からVLOOKUPで自動参照 【原価】黄色セルに実績を入力 各ルートの粗利率で採算の良し悪しを確認できます
A3: ルートコード | B3: ルート名 | C3: 集計月 (YYYY-MM) | D3: 売上 (VLOOKUP) | E3: 原価 （黄色セル入力） | L3: 粗利益 | M3: 粗利率 | N3: 採算判定 | O3: 主担当 案件 | P3: 前月比 売上 | Q3: 月間回収量 (kg推算)
E4: 人件費 | F4: 燃料費 | G4: 車両費 | H4: 処理費 | I4: 運搬費 | J4: その他 | K4: 合計
A5: 612-1 | B5: 運送（本社） | C5: 2024-07 | D5: =IFERROR(VLOOKUP(C5,▼売上原票!$A:$P,3,0),0) | E5: =SUMPRODUCT((▼従業員マスター!$A$6:$A$300="本社")*(▼従業員マスター!$G$6:$G$300="直接")*▼従業員マスター!$F$6:$F$300) | K5: =E5+F5+G5+H5+I5+J5 | L5: =D5-K5 | M5: =IF(D5<>0,L5/D5,0) | N5: =IF(D5=0,"—",IF(M5>=0.25,"◎ 優良",IF(M5>=0.15,"○ 良好",IF(M5>=0.05,"△ 要注意","× 赤字")))) | O5: C003一般 | P5: — | Q5: =IFERROR(D5/100,0)
A6: 612-1 | B6: 運送（本社） | C6: 2024-08 | D6: =IFERROR(VLOOKUP(C6,▼売上原票!$A:$P,3,0),0) | E6: =SUMPRODUCT((▼従業員マスター!$A$6:$A$300="本社")*(▼従業員マスター!$G$6:$G$300="直接")*▼従業員マスター!$F$6:$F$300) | K6: =E6+F6+G6+H6+I6+J6 | L6: =D6-K6 | M6: =IF(D6<>0,L6/D6,0) | N6: =IF(D6=0,"—",IF(M6>=0.25,"◎ 優良",IF(M6>=0.15,"○ 良好",IF(M6>=0.05,"△ 要注意","× 赤字")))) | O6: C003一般 | P6: =IF(D5<>0,D6/D5-1,"") | Q6: =IFERROR(D6/100,0)
A7: 612-1 | B7: 運送（本社） | C7: 2024-09 | D7: =IFERROR(VLOOKUP(C7,▼売上原票!$A:$P,3,0),0) | E7: =SUMPRODUCT((▼従業員マスター!$A$6:$A$300="本社")*(▼従業員マスター!$G$6:$G$300="直接")*▼従業員マスター!$F$6:$F$300) | K7: =E7+F7+G7+H7+I7+J7 | L7: =D7-K7 | M7: =IF(D7<>0,L7/D7,0) | N7: =IF(D7=0,"—",IF(M7>=0.25,"◎ 優良",IF(M7>=0.15,"○ 良好",IF(M7>=0.05,"△ 要注意","× 赤字")))) | O7: C003一般 | P7: =IF(D6<>0,D7/D6-1,"") | Q7: =IFERROR(D7/100,0)
A8: 612-1 | B8: 運送（本社） | C8: 2024-10 | D8: =IFERROR(VLOOKUP(C8,▼売上原票!$A:$P,3,0),0) | E8: =SUMPRODUCT((▼従業員マスター!$A$6:$A$300="本社")*(▼従業員マスター!$G$6:$G$300="直接")*▼従業員マスター!$F$6:$F$300) | K8: =E8+F8+G8+H8+I8+J8 | L8: =D8-K8 | M8: =IF(D8<>0,L8/D8,0) | N8: =IF(D8=0,"—",IF(M8>=0.25,"◎ 優良",IF(M8>=0.15,"○ 良好",IF(M8>=0.05,"△ 要注意","× 赤字")))) | O8: C003一般 | P8: =IF(D7<>0,D8/D7-1,"") | Q8: =IFERROR(D8/100,0)
A9: 612-1 | B9: 運送（本社） | C9: 2024-11 | D9: =IFERROR(VLOOKUP(C9,▼売上原票!$A:$P,3,0),0) | E9: =SUMPRODUCT((▼従業員マスター!$A$6:$A$300="本社")*(▼従業員マスター!$G$6:$G$300="直接")*▼従業員マスター!$F$6:$F$300) | K9: =E9+F9+G9+H9+I9+J9 | L9: =D9-K9 | M9: =IF(D9<>0,L9/D9,0) | N9: =IF(D9=0,"—",IF(M9>=0.25,"◎ 優良",IF(M9>=0.15,"○ 良好",IF(M9>=0.05,"△ 要注意","× 赤字")))) | O9: C003一般 | P9: =IF(D8<>0,D9/D8-1,"") | Q9: =IFERROR(D9/100,0)
A10: 612-1 | B10: 運送（本社） | C10: 2024-12 | D10: =IFERROR(VLOOKUP(C10,▼売上原票!$A:$P,3,0),0) | E10: =SUMPRODUCT((▼従業員マスター!$A$6:$A$300="本社")*(▼従業員マスター!$G$6:$G$300="直接")*▼従業員マスター!$F$6:$F$300) | K10: =E10+F10+G10+H10+I10+J10 | L10: =D10-K10 | M10: =IF(D10<>0,L10/D10,0) | N10: =IF(D10=0,"—",IF(M10>=0.25,"◎ 優良",IF(M10>=0.15,"○ 良好",IF(M10>=0.05,"△ 要注意","× 赤字")))) | O10: C003一般 | P10: =IF(D9<>0,D10/D9-1,"") | Q10: =IFERROR(D10/100,0)
A11: 612-1 | B11: 運送（本社） | C11: 2025-01 | D11: =IFERROR(VLOOKUP(C11,▼売上原票!$A:$P,3,0),0) | E11: =SUMPRODUCT((▼従業員マスター!$A$6:$A$300="本社")*(▼従業員マスター!$G$6:$G$300="直接")*▼従業員マスター!$F$6:$F$300) | K11: =E11+F11+G11+H11+I11+J11 | L11: =D11-K11 | M11: =IF(D11<>0,L11/D11,0) | N11: =IF(D11=0,"—",IF(M11>=0.25,"◎ 優良",IF(M11>=0.15,"○ 良好",IF(M11>=0.05,"△ 要注意","× 赤字")))) | O11: C003一般 | P11: =IF(D10<>0,D11/D10-1,"") | Q11: =IFERROR(D11/100,0)
A12: 612-1 | B12: 運送（本社） | C12: 2025-02 | D12: =IFERROR(VLOOKUP(C12,▼売上原票!$A:$P,3,0),0) | E12: =SUMPRODUCT((▼従業員マスター!$A$6:$A$300="本社")*(▼従業員マスター!$G$6:$G$300="直接")*▼従業員マスター!$F$6:$F$300) | K12: =E12+F12+G12+H12+I12+J12 | L12: =D12-K12 | M12: =IF(D12<>0,L12/D12,0) | N12: =IF(D12=0,"—",IF(M12>=0.25,"◎ 優良",IF(M12>=0.15,"○ 良好",IF(M12>=0.05,"△ 要注意","× 赤字")))) | O12: C003一般 | P12: =IF(D11<>0,D12/D11-1,"") | Q12: =IFERROR(D12/100,0)
A13: 612-1 | B13: 運送（本社） | C13: 2025-03 | D13: =IFERROR(VLOOKUP(C13,▼売上原票!$A:$P,3,0),0) | E13: =SUMPRODUCT((▼従業員マスター!$A$6:$A$300="本社")*(▼従業員マスター!$G$6:$G$300="直接")*▼従業員マスター!$F$6:$F$300) | K13: =E13+F13+G13+H13+I13+J13 | L13: =D13-K13 | M13: =IF(D13<>0,L13/D13,0) | N13: =IF(D13=0,"—",IF(M13>=0.25,"◎ 優良",IF(M13>=0.15,"○ 良好",IF(M13>=0.05,"△ 要注意","× 赤字")))) | O13: C003一般 | P13: =IF(D12<>0,D13/D12-1,"") | Q13: =IFERROR(D13/100,0)
A14: 612-1 | B14: 運送（本社） | C14: 2025-04 | D14: =IFERROR(VLOOKUP(C14,▼売上原票!$A:$P,3,0),0) | E14: =SUMPRODUCT((▼従業員マスター!$A$6:$A$300="本社")*(▼従業員マスター!$G$6:$G$300="直接")*▼従業員マスター!$F$6:$F$300) | K14: =E14+F14+G14+H14+I14+J14 | L14: =D14-K14 | M14: =IF(D14<>0,L14/D14,0) | N14: =IF(D14=0,"—",IF(M14>=0.25,"◎ 優良",IF(M14>=0.15,"○ 良好",IF(M14>=0.05,"△ 要注意","× 赤字")))) | O14: C003一般 | P14: =IF(D13<>0,D14/D13-1,"") | Q14: =IFERROR(D14/100,0)
A15: 612-1 | B15: 運送（本社） | C15: 2025-05 | D15: =IFERROR(VLOOKUP(C15,▼売上原票!$A:$P,3,0),0) | E15: =SUMPRODUCT((▼従業員マスター!$A$6:$A$300="本社")*(▼従業員マスター!$G$6:$G$300="直接")*▼従業員マスター!$F$6:$F$300) | K15: =E15+F15+G15+H15+I15+J15 | L15: =D15-K15 | M15: =IF(D15<>0,L15/D15,0) | N15: =IF(D15=0,"—",IF(M15>=0.25,"◎ 優良",IF(M15>=0.15,"○ 良好",IF(M15>=0.05,"△ 要注意","× 赤字")))) | O15: C003一般 | P15: =IF(D14<>0,D15/D14-1,"") | Q15: =IFERROR(D15/100,0)
A16: 612-1 | B16: 運送（本社） | C16: 2025-06 | D16: =IFERROR(VLOOKUP(C16,▼売上原票!$A:$P,3,0),0) | E16: =SUMPRODUCT((▼従業員マスター!$A$6:$A$300="本社")*(▼従業員マスター!$G$6:$G$300="直接")*▼従業員マスター!$F$6:$F$300) | K16: =E16+F16+G16+H16+I16+J16 | L16: =D16-K16 | M16: =IF(D16<>0,L16/D16,0) | N16: =IF(D16=0,"—",IF(M16>=0.25,"◎ 優良",IF(M16>=0.15,"○ 良好",IF(M16>=0.05,"△ 要注意","× 赤字")))) | O16: C003一般 | P16: =IF(D15<>0,D16/D15-1,"") | Q16: =IFERROR(D16/100,0)
A17: 612-1 | B17: 運送（本社） | C17: 2025-07 | D17: =IFERROR(VLOOKUP(C17,▼売上原票!$A:$P,3,0),0) | E17: =SUMPRODUCT((▼従業員マスター!$A$6:$A$300="本社")*(▼従業員マスター!$G$6:$G$300="直接")*▼従業員マスター!$F$6:$F$300) | K17: =E17+F17+G17+H17+I17+J17 | L17: =D17-K17 | M17: =IF(D17<>0,L17/D17,0) | N17: =IF(D17=0,"—",IF(M17>=0.25,"◎ 優良",IF(M17>=0.15,"○ 良好",IF(M17>=0.05,"△ 要注意","× 赤字")))) | O17: C003一般 | P17: =IF(D16<>0,D17/D16-1,"") | Q17: =IFERROR(D17/100,0)
... A21: 612-1 | B21: 運送（本社） | C21: 2025-11 | D21: =IFERROR(VLOOKUP(C21,▼売上原票!$A:$P,3,0),0) | E21: =SUMPRODUCT((▼従業員マスター!$A$6:$A$300="本社")*(▼従業員マスター!$G$6:$G$300="直接")*▼従業員マスター!$F$6:$F$300) | K21: =E21+F21+G21+H21+I21+J21 | L21: =D21-K21 | M21: =IF(D21<>0,L21/D21,0) | N21: =IF(D21=0,"—",IF(M21>=0.25,"◎ 優良",IF(M21>=0.15,"○ 良好",IF(M21>=0.05,"△ 要注意","× 赤字")))) | O21: C003一般 | P21: =IF(D20<>0,D21/D20-1,"") | Q21: =IFERROR(D21/100,0)
A23: 612-2 | B23: 入札（公共） | C23: 2024-07 | D23: =IFERROR(VLOOKUP(C23,▼売上原票!$A:$P,4,0),0) | E23: =SUMPRODUCT((▼従業員マスター!$A$6:$A$300="埼玉")*(▼従業員マスター!$G$6:$G$300="直接")*▼従業員マスター!$F$6:$F$300) | K23: =E23+F23+G23+H23+I23+J23 | L23: =D23-K23 | M23: =IF(D23<>0,L23/D23,0) | N23: =IF(D23=0,"—",IF(M23>=0.25,"◎ 優良",IF(M23>=0.15,"○ 良好",IF(M23>=0.05,"△ 要注意","× 赤字")))) | O23: C002都営 | P23: — | Q23: =IFERROR(D23/100,0)
A24: 612-2 | B24: 入札（公共） | C24: 2024-08 | D24: =IFERROR(VLOOKUP(C24,▼売上原票!$A:$P,4,0),0) | E24: =SUMPRODUCT((▼従業員マスター!$A$6:$A$300="埼玉")*(▼従業員マスター!$G$6:$G$300="直接")*▼従業員マスター!$F$6:$F$300) | K24: =E24+F24+G24+H24+I24+J24 | L24: =D24-K24 | M24: =IF(D24<>0,L24/D24,0) | N24: =IF(D24=0,"—",IF(M24>=0.25,"◎ 優良",IF(M24>=0.15,"○ 良好",IF(M24>=0.05,"△ 要注意","× 赤字")))) | O24: C002都営 | P24: =IF(D23<>0,D24/D23-1,"") | Q24: =IFERROR(D24/100,0)
A25: 612-2 | B25: 入札（公共） | C25: 2024-09 | D25: =IFERROR(VLOOKUP(C25,▼売上原票!$A:$P,4,0),0) | E25: =SUMPRODUCT((▼従業員マスター!$A$6:$A$300="埼玉")*(▼従業員マスター!$G$6:$G$300="直接")*▼従業員マスター!$F$6:$F$300) | K25: =E25+F25+G25+H25+I25+J25 | L25: =D25-K25 | M25: =IF(D25<>0,L25/D25,0) | N25: =IF(D25=0,"—",IF(M25>=0.25,"◎ 優良",IF(M25>=0.15,"○ 良好",IF(M25>=0.05,"△ 要注意","× 赤字")))) | O25: C002都営 | P25: =IF(D24<>0,D25/D24-1,"") | Q25: =IFERROR(D25/100,0)
A26: 612-2 | B26: 入札（公共） | C26: 2024-10 | D26: =IFERROR(VLOOKUP(C26,▼売上原票!$A:$P,4,0),0) | E26: =SUMPRODUCT((▼従業員マスター!$A$6:$A$300="埼玉")*(▼従業員マスター!$G$6:$G$300="直接")*▼従業員マスター!$F$6:$F$300) | K26: =E26+F26+G26+H26+I26+J26 | L26: =D26-K26 | M26: =IF(D26<>0,L26/D26,0) | N26: =IF(D26=0,"—",IF(M26>=0.25,"◎ 優良",IF(M26>=0.15,"○ 良好",IF(M26>=0.05,"△ 要注意","× 赤字")))) | O26: C002都営 | P26: =IF(D25<>0,D26/D25-1,"") | Q26: =IFERROR(D26/100,0)
A27: 612-2 | B27: 入札（公共） | C27: 2024-11 | D27: =IFERROR(VLOOKUP(C27,▼売上原票!$A:$P,4,0),0) | E27: =SUMPRODUCT((▼従業員マスター!$A$6:$A$300="埼玉")*(▼従業員マスター!$G$6:$G$300="直接")*▼従業員マスター!$F$6:$F$300) | K27: =E27+F27+G27+H27+I27+J27 | L27: =D27-K27 | M27: =IF(D27<>0,L27/D27,0) | N27: =IF(D27=0,"—",IF(M27>=0.25,"◎ 優良",IF(M27>=0.15,"○ 良好",IF(M27>=0.05,"△ 要注意","× 赤字")))) | O27: C002都営 | P27: =IF(D26<>0,D27/D26-1,"") | Q27: =IFERROR(D27/100,0)
A28: 612-2 | B28: 入札（公共） | C28: 2024-12 | D28: =IFERROR(VLOOKUP(C28,▼売上原票!$A:$P,4,0),0) | E28: =SUMPRODUCT((▼従業員マスター!$A$6:$A$300="埼玉")*(▼従業員マスター!$G$6:$G$300="直接")*▼従業員マスター!$F$6:$F$300) | K28: =E28+F28+G28+H28+I28+J28 | L28: =D28-K28 | M28: =IF(D28<>0,L28/D28,0) | N28: =IF(D28=0,"—",IF(M28>=0.25,"◎ 優良",IF(M28>=0.15,"○ 良好",IF(M28>=0.05,"△ 要注意","× 赤字")))) | O28: C002都営 | P28: =IF(D27<>0,D28/D27-1,"") | Q28: =IFERROR(D28/100,0)
A29: 612-2 | B29: 入札（公共） | C29: 2025-01 | D29: =IFERROR(VLOOKUP(C29,▼売上原票!$A:$P,4,0),0) | E29: =SUMPRODUCT((▼従業員マスター!$A$6:$A$300="埼玉")*(▼従業員マスター!$G$6:$G$300="直接")*▼従業員マスター!$F$6:$F$300) | K29: =E29+F29+G29+H29+I29+J29 | L29: =D29-K29 | M29: =IF(D29<>0,L29/D29,0) | N29: =IF(D29=0,"—",IF(M29>=0.25,"◎ 優良",IF(M29>=0.15,"○ 良好",IF(M29>=0.05,"△ 要注意","× 赤字")))) | O29: C002都営 | P29: =IF(D28<>0,D29/D28-1,"") | Q29: =IFERROR(D29/100,0)
A30: 612-2 | B30: 入札（公共） | C30: 2025-02 | D30: =IFERROR(VLOOKUP(C30,▼売上原票!$A:$P,4,0),0) | E30: =SUMPRODUCT((▼従業員マスター!$A$6:$A$300="埼玉")*(▼従業員マスター!$G$6:$G$300="直接")*▼従業員マスター!$F$6:$F$300) | K30: =E30+F30+G30+H30+I30+J30 | L30: =D30-K30 | M30: =IF(D30<>0,L30/D30,0) | N30: =IF(D30=0,"—",IF(M30>=0.25,"◎ 優良",IF(M30>=0.15,"○ 良好",IF(M30>=0.05,"△ 要注意","× 赤字")))) | O30: C002都営 | P30: =IF(D29<>0,D30/D29-1,"") | Q30: =IFERROR(D30/100,0)
A31: 612-2 | B31: 入札（公共） | C31: 2025-03 | D31: =IFERROR(VLOOKUP(C31,▼売上原票!$A:$P,4,0),0) | E31: =SUMPRODUCT((▼従業員マスター!$A$6:$A$300="埼玉")*(▼従業員マスター!$G$6:$G$300="直接")*▼従業員マスター!$F$6:$F$300) | K31: =E31+F31+G31+H31+I31+J31 | L31: =D31-K31 | M31: =IF(D31<>0,L31/D31,0) | N31: =IF(D31=0,"—",IF(M31>=0.25,"◎ 優良",IF(M31>=0.15,"○ 良好",IF(M31>=0.05,"△ 要注意","× 赤字")))) | O31: C002都営 | P31: =IF(D30<>0,D31/D30-1,"") | Q31: =IFERROR(D31/100,0)
A32: 612-2 | B32: 入札（公共） | C32: 2025-04 | D32: =IFERROR(VLOOKUP(C32,▼売上原票!$A:$P,4,0),0) | E32: =SUMPRODUCT((▼従業員マスター!$A$6:$A$300="埼玉")*(▼従業員マスター!$G$6:$G$300="直接")*▼従業員マスター!$F$6:$F$300) | K32: =E32+F32+G32+H32+I32+J32 | L32: =D32-K32 | M32: =IF(D32<>0,L32/D32,0) | N32: =IF(D32=0,"—",IF(M32>=0.25,"◎ 優良",IF(M32>=0.15,"○ 良好",IF(M32>=0.05,"△ 要注意","× 赤字")))) | O32: C002都営 | P32: =IF(D31<>0,D32/D31-1,"") | Q32: =IFERROR(D32/100,0)
A33: 612-2 | B33: 入札（公共） | C33: 2025-05 | D33: =IFERROR(VLOOKUP(C33,▼売上原票!$A:$P,4,0),0) | E33: =SUMPRODUCT((▼従業員マスター!$A$6:$A$300="埼玉")*(▼従業員マスター!$G$6:$G$300="直接")*▼従業員マスター!$F$6:$F$300) | K33: =E33+F33+G33+H33+I33+J33 | L33: =D33-K33 | M33: =IF(D33<>0,L33/D33,0) | N33: =IF(D33=0,"—",IF(M33>=0.25,"◎ 優良",IF(M33>=0.15,"○ 良好",IF(M33>=0.05,"△ 要注意","× 赤字")))) | O33: C002都営 | P33: =IF(D32<>0,D33/D32-1,"") | Q33: =IFERROR(D33/100,0)
A34: 612-2 | B34: 入札（公共） | C34: 2025-06 | D34: =IFERROR(VLOOKUP(C34,▼売上原票!$A:$P,4,0),0) | E34: =SUMPRODUCT((▼従業員マスター!$A$6:$A$300="埼玉")*(▼従業員マスター!$G$6:$G$300="直接")*▼従業員マスター!$F$6:$F$300) | K34: =E34+F34+G34+H34+I34+J34 | L34: =D34-K34 | M34: =IF(D34<>0,L34/D34,0) | N34: =IF(D34=0,"—",IF(M34>=0.25,"◎ 優良",IF(M34>=0.15,"○ 良好",IF(M34>=0.05,"△ 要注意","× 赤字")))) | O34: C002都営 | P34: =IF(D33<>0,D34/D33-1,"") | Q34: =IFERROR(D34/100,0)
A35: 612-2 | B35: 入札（公共） | C35: 2025-07 | D35: =IFERROR(VLOOKUP(C35,▼売上原票!$A:$P,4,0),0) | E35: =SUMPRODUCT((▼従業員マスター!$A$6:$A$300="埼玉")*(▼従業員マスター!$G$6:$G$300="直接")*▼従業員マスター!$F$6:$F$300) | K35: =E35+F35+G35+H35+I35+J35 | L35: =D35-K35 | M35: =IF(D35<>0,L35/D35,0) | N35: =IF(D35=0,"—",IF(M35>=0.25,"◎ 優良",IF(M35>=0.15,"○ 良好",IF(M35>=0.05,"△ 要注意","× 赤字")))) | O35: C002都営 | P35: =IF(D34<>0,D35/D34-1,"") | Q35: =IFERROR(D35/100,0)
... A39: 612-2 | B39: 入札（公共） | C39: 2025-11 | D39: =IFERROR(VLOOKUP(C39,▼売上原票!$A:$P,4,0),0) | E39: =SUMPRODUCT((▼従業員マスター!$A$6:$A$300="埼玉")*(▼従業員マスター!$G$6:$G$300="直接")*▼従業員マスター!$F$6:$F$300) | K39: =E39+F39+G39+H39+I39+J39 | L39: =D39-K39 | M39: =IF(D39<>0,L39/D39,0) | N39: =IF(D39=0,"—",IF(M39>=0.25,"◎ 優良",IF(M39>=0.15,"○ 良好",IF(M39>=0.05,"△ 要注意","× 赤字")))) | O39: C002都営 | P39: =IF(D38<>0,D39/D38-1,"") | Q39: =IFERROR(D39/100,0)
A41: 613-1 | B41: 車輌 | C41: 2024-07 | D41: =IFERROR(VLOOKUP(C41,▼売上原票!$A:$P,5,0),0) | K41: =E41+F41+G41+H41+I41+J41 | L41: =D41-K41 | M41: =IF(D41<>0,L41/D41,0) | N41: =IF(D41=0,"—",IF(M41>=0.25,"◎ 優良",IF(M41>=0.15,"○ 良好",IF(M41>=0.05,"△ 要注意","× 赤字")))) | O41: C003一般 | P41: — | Q41: =IFERROR(D41/100,0)
A42: 613-1 | B42: 車輌 | C42: 2024-08 | D42: =IFERROR(VLOOKUP(C42,▼売上原票!$A:$P,5,0),0) | K42: =E42+F42+G42+H42+I42+J42 | L42: =D42-K42 | M42: =IF(D42<>0,L42/D42,0) | N42: =IF(D42=0,"—",IF(M42>=0.25,"◎ 優良",IF(M42>=0.15,"○ 良好",IF(M42>=0.05,"△ 要注意","× 赤字")))) | O42: C003一般 | P42: =IF(D41<>0,D42/D41-1,"") | Q42: =IFERROR(D42/100,0)
A43: 613-1 | B43: 車輌 | C43: 2024-09 | D43: =IFERROR(VLOOKUP(C43,▼売上原票!$A:$P,5,0),0) | K43: =E43+F43+G43+H43+I43+J43 | L43: =D43-K43 | M43: =IF(D43<>0,L43/D43,0) | N43: =IF(D43=0,"—",IF(M43>=0.25,"◎ 優良",IF(M43>=0.15,"○ 良好",IF(M43>=0.05,"△ 要注意","× 赤字")))) | O43: C003一般 | P43: =IF(D42<>0,D43/D42-1,"") | Q43: =IFERROR(D43/100,0)
A44: 613-1 | B44: 車輌 | C44: 2024-10 | D44: =IFERROR(VLOOKUP(C44,▼売上原票!$A:$P,5,0),0) | K44: =E44+F44+G44+H44+I44+J44 | L44: =D44-K44 | M44: =IF(D44<>0,L44/D44,0) | N44: =IF(D44=0,"—",IF(M44>=0.25,"◎ 優良",IF(M44>=0.15,"○ 良好",IF(M44>=0.05,"△ 要注意","× 赤字")))) | O44: C003一般 | P44: =IF(D43<>0,D44/D43-1,"") | Q44: =IFERROR(D44/100,0)
A45: 613-1 | B45: 車輌 | C45: 2024-11 | D45: =IFERROR(VLOOKUP(C45,▼売上原票!$A:$P,5,0),0) | K45: =E45+F45+G45+H45+I45+J45 | L45: =D45-K45 | M45: =IF(D45<>0,L45/D45,0) | N45: =IF(D45=0,"—",IF(M45>=0.25,"◎ 優良",IF(M45>=0.15,"○ 良好",IF(M45>=0.05,"△ 要注意","× 赤字")))) | O45: C003一般 | P45: =IF(D44<>0,D45/D44-1,"") | Q45: =IFERROR(D45/100,0)
A46: 613-1 | B46: 車輌 | C46: 2024-12 | D46: =IFERROR(VLOOKUP(C46,▼売上原票!$A:$P,5,0),0) | K46: =E46+F46+G46+H46+I46+J46 | L46: =D46-K46 | M46: =IF(D46<>0,L46/D46,0) | N46: =IF(D46=0,"—",IF(M46>=0.25,"◎ 優良",IF(M46>=0.15,"○ 良好",IF(M46>=0.05,"△ 要注意","× 赤字")))) | O46: C003一般 | P46: =IF(D45<>0,D46/D45-1,"") | Q46: =IFERROR(D46/100,0)
A47: 613-1 | B47: 車輌 | C47: 2025-01 | D47: =IFERROR(VLOOKUP(C47,▼売上原票!$A:$P,5,0),0) | K47: =E47+F47+G47+H47+I47+J47 | L47: =D47-K47 | M47: =IF(D47<>0,L47/D47,0) | N47: =IF(D47=0,"—",IF(M47>=0.25,"◎ 優良",IF(M47>=0.15,"○ 良好",IF(M47>=0.05,"△ 要注意","× 赤字")))) | O47: C003一般 | P47: =IF(D46<>0,D47/D46-1,"") | Q47: =IFERROR(D47/100,0)
A48: 613-1 | B48: 車輌 | C48: 2025-02 | D48: =IFERROR(VLOOKUP(C48,▼売上原票!$A:$P,5,0),0) | K48: =E48+F48+G48+H48+I48+J48 | L48: =D48-K48 | M48: =IF(D48<>0,L48/D48,0) | N48: =IF(D48=0,"—",IF(M48>=0.25,"◎ 優良",IF(M48>=0.15,"○ 良好",IF(M48>=0.05,"△ 要注意","× 赤字")))) | O48: C003一般 | P48: =IF(D47<>0,D48/D47-1,"") | Q48: =IFERROR(D48/100,0)
...

Sheet ▼売上原票
A1: ▼売上原票 月次売上実績（科目別・税抜） ※このシートは直接編集しないでください
A2: 【毎月の更新方法】 新しい月のデータを最終行の下に1行追加してください。A列=YYYY-MM、C〜M列=各科目売上（税抜円）
A3: 年月 ★VLOOKUPキー | B3: R表記 | C3: 612-1 運送（本社） | D3: 612-2 入札（公共） | E3: 613-1 車輌 | F3: 613-2 KC | G3: 614-1 コンテナ | H3: 614-2 ENDO | I3: 614-3 現金 | J3: 615-1 板橋 | K3: 615-2 新横浜 | L3: 615-3 現金2 | M3: 615-4 有価物 | N3: 合計 (税抜) | O3: 消費税 (△) | P3: 合計 (税込)
A4: 2024-07 | B4: R6.7 | C4: 13754437 | D4: 42726740 | E4: 777000 | F4: 40000 | G4: 504500 | H4: 527664 | I4: 261000 | J4: 25593317 | K4: 4417112 | L4: 36000 | M4: 138460 | N4: 88776230 | O4: -80705664 | P4: =IF(N4<>"",N4+O4,"")
A5: 2024-08 | B5: R6.8 | C5: 13060970 | D5: 36972090 | E5: 789000 | F5: 1000228 | G5: 507200 | H5: 518000 | J5: 20527297 | K5: 4953790 | L5: 57000 | M5: 172726 | N5: 78558301 | O5: -71416637 | P5: =IF(N5<>"",N5+O5,"")
A6: 2024-09 | B6: R6.9 | C6: 13837910 | D6: 37268605 | E6: 1143000 | G6: 513500 | H6: 480000 | J6: 22121458 | K6: 4072534 | L6: 54000 | M6: 162126 | N6: 79653133 | O6: -72411939 | P6: =IF(N6<>"",N6+O6,"")
A7: 2024-10 | B7: R6.10 | C7: 14538480 | D7: 39318469 | E7: 2859000 | F7: 3879338 | G7: 519500 | H7: 665902 | I7: 45000 | J7: 20930409 | K7: 4513589 | L7: 106000 | M7: 132040 | N7: 87507727 | O7: -79552479 | P7: =IF(N7<>"",N7+O7,"")
A8: 2024-11 | B8: R6.11 | C8: 12832260 | D8: 40166406 | E8: 891000 | F8: 2729582 | G8: 552500 | H8: 962040 | J8: 21039598 | K8: 4677613 | L8: 54000 | M8: 131610 | N8: 84036609 | O8: -76396917 | P8: =IF(N8<>"",N8+O8,"")
A9: 2024-12 | B9: R6.12 | C9: 13385794 | D9: 36230090 | E9: 885000 | F9: 3927473 | G9: 543500 | H9: 247700 | I9: 928500 | J9: 21774932 | K9: 4842835 | L9: 27000 | M9: 212926 | N9: 83005750 | O9: -75459773 | P9: =IF(N9<>"",N9+O9,"")
A10: 2025-01 | B10: R7.1 | C10: 11619926 | D10: 37239620 | F10: 1249028 | G10: 534500 | H10: 300000 | I10: 70000 | J10: 19408606 | K10: 4149715 | L10: 18000 | M10: 133330 | N10: 74722725 | O10: -67929750 | P10: =IF(N10<>"",N10+O10,"")
A11: 2025-02 | B11: R7.2 | C11: 12256849 | D11: 35273064 | E11: 716000 | G11: 534500 | H11: 150400 | J11: 18823147 | K11: 3791480 | L11: 75864 | M11: 163880 | N11: 71785184 | O11: -65259258 | P11: =IF(N11<>"",N11+O11,"")
A12: 2025-03 | B12: R7.3 | C12: 12036342 | D12: 39891431 | F12: 4399519 | G12: 534500 | H12: 35728 | I12: 177600 | J12: 21429591 | K12: 5604911 | L12: 73000 | M12: 167470 | N12: 84350092 | O12: -76681902 | P12: =IF(N12<>"",N12+O12,"")
A13: 2025-04 | B13: R7.4 | C13: 13732489 | D13: 42565460 | E13: 320000 | G13: 579000 | H13: 20000 | I13: 385190 | J13: 20293634 | K13: 4392253 | L13: 54000 | M13: 126695 | N13: 82468721 | O13: -74971565 | P13: =IF(N13<>"",N13+O13,"")
A14: 2025-05 | B14: R7.5 | C14: 12433945 | D14: 42621987 | E14: 24000 | G14: 399500 | H14: 375209 | I14: 4439900 | J14: 20536694 | K14: 4686122 | L14: 49068 | M14: 116600 | N14: 85683025 | O14: -77893659 | P14: =IF(N14<>"",N14+O14,"")
A15: 2025-06 | B15: R7.6 | C15: 12725923 | D15: 42039492 | E15: 560000 | F15: 6678437 | G15: 639500 | H15: 66155 | I15: 811380 | J15: 21382460 | K15: 4686956 | L15: 282934 | M15: 233890 | N15: 90107127 | O15: -81915570 | P15: =IF(N15<>"",N15+O15,"")
A16: 2025-07 | B16: R7.7 | C16: 14033460 | D16: 49551795 | E16: 70400 | G16: 439450 | H16: 522775 | I16: 3465 | J16: 24309231 | K16: 5799867 | L16: 19800 | M16: 299751 | N16: 95049994 | O16: -86409085 | P16: =IF(N16<>"",N16+O16,"")
A17: 2025-08 | B17: R7.8 | C17: 12775187 | D17: 45672694 | E17: 1859000 | F17: 6057720 | G17: 703450 | H17: 995236 | I17: 500 | J17: 21710565 | K17: 6235942 | L17: 85140 | M17: 297500 | N17: 96392934 | O17: -87629940 | P17: =IF(N17<>"",N17+O17,"")
